Workbook
Name POWER_USER_LINK_EDA81D4C_E424_4C6E_8A36_5F1A4994EB75: "Summary!R4C1:R17C2"

Sheet Cover
C7: Title | D7: Project Crystal - JV Day 1 Readiness Plan
C9: Description | D9: All actions required to achieve JV Day-1 operational readiness
C11: Date | D11: =TODAY() -> 46091

Sheet Summary
B2: REQUIREMENTS BY OWNER | C2: =SUM(C4:C26) -> 38 | E2: =SUM(E4:E26) -> 14 | F2: =SUM(F4:F26) -> 23 | G2: =SUM(G4:G26) -> 1 | I2: REQUIREMENTS BY CATEGORY | J2: =SUM(J4:J20) -> 105 | K2: =SUM(K4:K20) -> 81 | M2: =SUM(M4:M20) -> 23 | N2: =SUM(N4:N20) -> 1
B3: Owner | C3: Total | E3: Completed | F3: On-track | G3: Delayed | I3: Workstream | J3: Total | K3: Not started | M3: On-track | N3: Delayed
B4: Hassen Moolla | C4: =SUM(D4:G4) -> 9 | E4: =(COUNTIFS('JV Readiness Plan'!$E:$E,$B4,'JV Readiness Plan'!$F:$F,E$3)) -> 3 | F4: =(COUNTIFS('JV Readiness Plan'!$E:$E,$B4,'JV Readiness Plan'!$F:$F,F$3)) -> 5 | G4: =(COUNTIFS('JV Readiness Plan'!$E:$E,$B4,'JV Readiness Plan'!$F:$F,G$3)) -> 1 | I4: Budget and BP | J4: =SUM(K4:N4) -> 6 | K4: =(COUNTIFS('JV Readiness Plan'!$B:$B,$I4,'JV Readiness Plan'!$F:$F,K$3)) -> 4 | M4: =(COUNTIFS('JV Readiness Plan'!$B:$B,$I4,'JV Readiness Plan'!$F:$F,M$3)) -> 2 | N4: =(COUNTIFS('JV Readiness Plan'!$B:$B,$I4,'JV Readiness Plan'!$F:$F,N$3)) -> 0
B5: Muddassar Khan | C5: =SUM(D5:G5) -> 10 | E5: =(COUNTIFS('JV Readiness Plan'!$E:$E,$B5,'JV Readiness Plan'!$F:$F,E$3)) -> 5 | F5: =(COUNTIFS('JV Readiness Plan'!$E:$E,$B5,'JV Readiness Plan'!$F:$F,F$3)) -> 5 | G5: =(COUNTIFS('JV Readiness Plan'!$E:$E,$B5,'JV Readiness Plan'!$F:$F,G$3)) -> 0 | I5: TSA | J5: =SUM(K5:N5) -> 4 | K5: =(COUNTIFS('JV Readiness Plan'!$B:$B,$I5,'JV Readiness Plan'!$F:$F,K$3)) -> 1 | M5: =(COUNTIFS('JV Readiness Plan'!$B:$B,$I5,'JV Readiness Plan'!$F:$F,M$3)) -> 3 | N5: =(COUNTIFS('JV Readiness Plan'!$B:$B,$I5,'JV Readiness Plan'!$F:$F,N$3)) -> 0
B6: Ramesh Murugesan | C6: =SUM(D6:G6) -> 2 | E6: =(COUNTIFS('JV Readiness Plan'!$E:$E,$B6,'JV Readiness Plan'!$F:$F,E$3)) -> 1 | F6: =(COUNTIFS('JV Readiness Plan'!$E:$E,$B6,'JV Readiness Plan'!$F:$F,F$3)) -> 1 | G6: =(COUNTIFS('JV Readiness Plan'!$E:$E,$B6,'JV Readiness Plan'!$F:$F,G$3)) -> 0 | I6: GSA | J6: =SUM(K6:N6) -> 6 | K6: =(COUNTIFS('JV Readiness Plan'!$B:$B,$I6,'JV Readiness Plan'!$F:$F,K$3)) -> 2 | M6: =(COUNTIFS('JV Readiness Plan'!$B:$B,$I6,'JV Readiness Plan'!$F:$F,M$3)) -> 3 | N6: =(COUNTIFS('JV Readiness Plan'!$B:$B,$I6,'JV Readiness Plan'!$F:$F,N$3)) -> 1
B7: Mawiyah Alqaed | C7: =SUM(D7:G7) -> 1 | E7: =(COUNTIFS('JV Readiness Plan'!$E:$E,$B7,'JV Readiness Plan'!$F:$F,E$3)) -> 1 | F7: =(COUNTIFS('JV Readiness Plan'!$E:$E,$B7,'JV Readiness Plan'!$F:$F,F$3)) -> 0 | G7: =(COUNTIFS('JV Readiness Plan'!$E:$E,$B7,'JV Readiness Plan'!$F:$F,G$3)) -> 0 | I7: DoA | J7: =SUM(K7:N7) -> 2 | K7: =(COUNTIFS('JV Readiness Plan'!$B:$B,$I7,'JV Readiness Plan'!$F:$F,K$3)) -> 1 | M7: =(COUNTIFS('JV Readiness Plan'!$B:$B,$I7,'JV Readiness Plan'!$F:$F,M$3)) -> 1 | N7: =(COUNTIFS('JV Readiness Plan'!$B:$B,$I7,'JV Readiness Plan'!$F:$F,N$3)) -> 0
B8: Aseel Alnafea | C8: =SUM(D8:G8) -> 3 | E8: =(COUNTIFS('JV Readiness Plan'!$E:$E,$B8,'JV Readiness Plan'!$F:$F,E$3)) -> 0 | F8: =(COUNTIFS('JV Readiness Plan'!$E:$E,$B8,'JV Readiness Plan'!$F:$F,F$3)) -> 3 | G8: =(COUNTIFS('JV Readiness Plan'!$E:$E,$B8,'JV Readiness Plan'!$F:$F,G$3)) -> 0 | I8: Secondment | J8: =SUM(K8:N8) -> 4 | K8: =(COUNTIFS('JV Readiness Plan'!$B:$B,$I8,'JV Readiness Plan'!$F:$F,K$3)) -> 2 | M8: =(COUNTIFS('JV Readiness Plan'!$B:$B,$I8,'JV Readiness Plan'!$F:$F,M$3)) -> 2 | N8: =(COUNTIFS('JV Readiness Plan'!$B:$B,$I8,'JV Readiness Plan'!$F:$F,N$3)) -> 0
B9: Rene Thumbran | C9: =SUM(D9:G9) -> 2 | E9: =(COUNTIFS('JV Readiness Plan'!$E:$E,$B9,'JV Readiness Plan'!$F:$F,E$3)) -> 0 | F9: =(COUNTIFS('JV Readiness Plan'!$E:$E,$B9,'JV Readiness Plan'!$F:$F,F$3)) -> 2 | G9: =(COUNTIFS('JV Readiness Plan'!$E:$E,$B9,'JV Readiness Plan'!$F:$F,G$3)) -> 0 | I9: SHA documentation | J9: =SUM(K9:N9) -> 8 | K9: =(COUNTIFS('JV Readiness Plan'!$B:$B,$I9,'JV Readiness Plan'!$F:$F,K$3)) -> 2 | M9: =(COUNTIFS('JV Readiness Plan'!$B:$B,$I9,'JV Readiness Plan'!$F:$F,M$3)) -> 6 | N9: =(COUNTIFS('JV Readiness Plan'!$B:$B,$I9,'JV Readiness Plan'!$F:$F,N$3)) -> 0
B10: Mohammed Al-Hamed | C10: =SUM(D10:G10) -> 3 | E10: =(COUNTIFS('JV Readiness Plan'!$E:$E,$B10,'JV Readiness Plan'!$F:$F,E$3)) -> 1 | F10: =(COUNTIFS('JV Readiness Plan'!$E:$E,$B10,'JV Readiness Plan'!$F:$F,F$3)) -> 2 | G10: =(COUNTIFS('JV Readiness Plan'!$E:$E,$B10,'JV Readiness Plan'!$F:$F,G$3)) -> 0 | I10: Corporate approval | J10: =SUM(K10:N10) -> 4 | K10: =(COUNTIFS('JV Readiness Plan'!$B:$B,$I10,'JV Readiness Plan'!$F:$F,K$3)) -> 2 | M10: =(COUNTIFS('JV Readiness Plan'!$B:$B,$I10,'JV Readiness Plan'!$F:$F,M$3)) -> 2 | N10: =(COUNTIFS('JV Readiness Plan'!$B:$B,$I10,'JV Readiness Plan'!$F:$F,N$3)) -> 0
B11: Omar Jabart | C11: =SUM(D11:G11) -> 2 | E11: =(COUNTIFS('JV Readiness Plan'!$E:$E,$B11,'JV Readiness Plan'!$F:$F,E$3)) -> 1 | F11: =(COUNTIFS('JV Readiness Plan'!$E:$E,$B11,'JV Readiness Plan'!$F:$F,F$3)) -> 1 | G11: =(COUNTIFS('JV Readiness Plan'!$E:$E,$B11,'JV Readiness Plan'!$F:$F,G$3)) -> 0 | I11: Governance | J11: =SUM(K11:N11) -> 19 | K11: =(COUNTIFS('JV Readiness Plan'!$B:$B,$I11,'JV Readiness Plan'!$F:$F,K$3)) -> 19 | M11: =(COUNTIFS('JV Readiness Plan'!$B:$B,$I11,'JV Readiness Plan'!$F:$F,M$3)) -> 0 | N11: =(COUNTIFS('JV Readiness Plan'!$B:$B,$I11,'JV Readiness Plan'!$F:$F,N$3)) -> 0
B12: Faraj Al Dossary | C12: =SUM(D12:G12) -> 1 | E12: =(COUNTIFS('JV Readiness Plan'!$E:$E,$B12,'JV Readiness Plan'!$F:$F,E$3)) -> 0 | F12: =(COUNTIFS('JV Readiness Plan'!$E:$E,$B12,'JV Readiness Plan'!$F:$F,F$3)) -> 1 | G12: =(COUNTIFS('JV Readiness Plan'!$E:$E,$B12,'JV Readiness Plan'!$F:$F,G$3)) -> 0 | I12: Legal | J12: =SUM(K12:N12) -> 6 | K12: =(COUNTIFS('JV Readiness Plan'!$B:$B,$I12,'JV Readiness Plan'!$F:$F,K$3)) -> 6 | M12: =(COUNTIFS('JV Readiness Plan'!$B:$B,$I12,'JV Readiness Plan'!$F:$F,M$3)) -> 0 | N12: =(COUNTIFS('JV Readiness Plan'!$B:$B,$I12,'JV Readiness Plan'!$F:$F,N$3)) -> 0
B13: Abdulrahman Abdullah Al-zahrani | C13: =SUM(D13:G13) -> 0 | E13: =(COUNTIFS('JV Readiness Plan'!$E:$E,$B13,'JV Readiness Plan'!$F:$F,E$3)) -> 0 | F13: =(COUNTIFS('JV Readiness Plan'!$E:$E,$B13,'JV Readiness Plan'!$F:$F,F$3)) -> 0 | G13: =(COUNTIFS('JV Readiness Plan'!$E:$E,$B13,'JV Readiness Plan'!$F:$F,G$3)) -> 0 | I13: GR | J13: =SUM(K13:N13) -> 4 | K13: =(COUNTIFS('JV Readiness Plan'!$B:$B,$I13,'JV Readiness Plan'!$F:$F,K$3)) -> 4 | M13: =(COUNTIFS('JV Readiness Plan'!$B:$B,$I13,'JV Readiness Plan'!$F:$F,M$3)) -> 0 | N13: =(COUNTIFS('JV Readiness Plan'!$B:$B,$I13,'JV Readiness Plan'!$F:$F,N$3)) -> 0
B14: Fathima Mahomed | C14: =SUM(D14:G14) -> 1 | E14: =(COUNTIFS('JV Readiness Plan'!$E:$E,$B14,'JV Readiness Plan'!$F:$F,E$3)) -> 0 | F14: =(COUNTIFS('JV Readiness Plan'!$E:$E,$B14,'JV Readiness Plan'!$F:$F,F$3)) -> 1 | G14: =(COUNTIFS('JV Readiness Plan'!$E:$E,$B14,'JV Readiness Plan'!$F:$F,G$3)) -> 0 | I14: HR | J14: =SUM(K14:N14) -> 6 | K14: =(COUNTIFS('JV Readiness Plan'!$B:$B,$I14,'JV Readiness Plan'!$F:$F,K$3)) -> 5 | M14: =(COUNTIFS('JV Readiness Plan'!$B:$B,$I14,'JV Readiness Plan'!$F:$F,M$3)) -> 1 | N14: =(COUNTIFS('JV Readiness Plan'!$B:$B,$I14,'JV Readiness Plan'!$F:$F,N$3)) -> 0
B15: Muddassar/ Mohammed | C15: =SUM(D15:G15) -> 0 | E15: =(COUNTIFS('JV Readiness Plan'!$E:$E,$B15,'JV Readiness Plan'!$F:$F,E$3)) -> 0 | F15: =(COUNTIFS('JV Readiness Plan'!$E:$E,$B15,'JV Readiness Plan'!$F:$F,F$3)) -> 0 | G15: =(COUNTIFS('JV Readiness Plan'!$E:$E,$B15,'JV Readiness Plan'!$F:$F,G$3)) -> 0 | I15: HSSE | J15: =SUM(K15:N15) -> 6 | K15: =(COUNTIFS('JV Readiness Plan'!$B:$B,$I15,'JV Readiness Plan'!$F:$F,K$3)) -> 5 | M15: =(COUNTIFS('JV Readiness Plan'!$B:$B,$I15,'JV Readiness Plan'!$F:$F,M$3)) -> 1 | N15: =(COUNTIFS('JV Readiness Plan'!$B:$B,$I15,'JV Readiness Plan'!$F:$F,N$3)) -> 0
... B20: Maaden and Aramco CEOs | C20: =SUM(D20:G20) -> 0 | E20: =(COUNTIFS('JV Readiness Plan'!$E:$E,$B20,'JV Readiness Plan'!$F:$F,E$3)) -> 0 | F20: =(COUNTIFS('JV Readiness Plan'!$E:$E,$B20,'JV Readiness Plan'!$F:$F,F$3)) -> 0 | G20: =(COUNTIFS('JV Readiness Plan'!$E:$E,$B20,'JV Readiness Plan'!$F:$F,G$3)) -> 0 | I20: Facilities | J20: =SUM(K20:N20) -> 1 | K20: =(COUNTIFS('JV Readiness Plan'!$B:$B,$I20,'JV Readiness Plan'!$F:$F,K$3)) -> 1 | M20: =(COUNTIFS('JV Readiness Plan'!$B:$B,$I20,'JV Readiness Plan'!$F:$F,M$3)) -> 0 | N20: =(COUNTIFS('JV Readiness Plan'!$B:$B,$I20,'JV Readiness Plan'!$F:$F,N$3)) -> 0
B21: Abdullah Alzamil | C21: =SUM(D21:G21) -> 0 | E21: =(COUNTIFS('JV Readiness Plan'!$E:$E,$B21,'JV Readiness Plan'!$F:$F,E$3)) -> 0 | F21: =(COUNTIFS('JV Readiness Plan'!$E:$E,$B21,'JV Readiness Plan'!$F:$F,F$3)) -> 0 | G21: =(COUNTIFS('JV Readiness Plan'!$E:$E,$B21,'JV Readiness Plan'!$F:$F,G$3)) -> 0
B22: Karim Mehboob | C22: =SUM(D22:G22) -> 0 | E22: =(COUNTIFS('JV Readiness Plan'!$E:$E,$B22,'JV Readiness Plan'!$F:$F,E$3)) -> 0 | F22: =(COUNTIFS('JV Readiness Plan'!$E:$E,$B22,'JV Readiness Plan'!$F:$F,F$3)) -> 0 | G22: =(COUNTIFS('JV Readiness Plan'!$E:$E,$B22,'JV Readiness Plan'!$F:$F,G$3)) -> 0
B23: Marwan Sutan | C23: =SUM(D23:G23) -> 0 | E23: =(COUNTIFS('JV Readiness Plan'!$E:$E,$B23,'JV Readiness Plan'!$F:$F,E$3)) -> 0 | F23: =(COUNTIFS('JV Readiness Plan'!$E:$E,$B23,'JV Readiness Plan'!$F:$F,F$3)) -> 0 | G23: =(COUNTIFS('JV Readiness Plan'!$E:$E,$B23,'JV Readiness Plan'!$F:$F,G$3)) -> 0
B24: Raud Alsuwailem | C24: =SUM(D24:G24) -> 0 | E24: =(COUNTIFS('JV Readiness Plan'!$E:$E,$B24,'JV Readiness Plan'!$F:$F,E$3)) -> 0 | F24: =(COUNTIFS('JV Readiness Plan'!$E:$E,$B24,'JV Readiness Plan'!$F:$F,F$3)) -> 0 | G24: =(COUNTIFS('JV Readiness Plan'!$E:$E,$B24,'JV Readiness Plan'!$F:$F,G$3)) -> 0
B25: Governance dept | C25: =SUM(D25:G25) -> 0 | E25: =(COUNTIFS('JV Readiness Plan'!$E:$E,$B25,'JV Readiness Plan'!$F:$F,E$3)) -> 0 | F25: =(COUNTIFS('JV Readiness Plan'!$E:$E,$B25,'JV Readiness Plan'!$F:$F,F$3)) -> 0 | G25: =(COUNTIFS('JV Readiness Plan'!$E:$E,$B25,'JV Readiness Plan'!$F:$F,G$3)) -> 0
B26: Raoof Madathil | C26: =SUM(D26:G26) -> 0 | E26: =(COUNTIFS('JV Readiness Plan'!$E:$E,$B26,'JV Readiness Plan'!$F:$F,E$3)) -> 0 | F26: =(COUNTIFS('JV Readiness Plan'!$E:$E,$B26,'JV Readiness Plan'!$F:$F,F$3)) -> 0 | G26: =(COUNTIFS('JV Readiness Plan'!$E:$E,$B26,'JV Readiness Plan'!$F:$F,G$3)) -> 0
G123: 46090

Sheet JV Readiness Plan
A1: PROJECT CRYSTAL - JV DAY-1 READINESS PLAN | H1: Day-1 target date | I1: =MAX(I4:I133) -> 46260
A3: Workstream | B3: Category | C3: Requirement | D3: Action | E3: Owner | F3: Status | G3: Start date | H3: Duration | I3: End date | J3: Target Completion (%) | K3: Actual Completion (%) | L3: Notes
B4: Budget and Business Plan | G4: =MIN(G5:G14) -> 46054 | H4: =I4-G4 -> 58 | I4: =MAX(I5:I14) -> 46112
A5: SHA | B5: Budget and BP | C5: Budget & BP Roles & Data Sources | D5: Clarify roles and responsibilities across Maaden finance and technical teams. Define who provides what, sources of information, and internal points of contact for each workstream. | E5: Hassen Moolla | F5: Completed | G5: 46054 | H5: 14 | I5: =G5+H5 -> 46068 | J5: =IFERROR(MAX(0,MIN(1,(TODAY()-G5)/(I5-G5))),"") -> 1 | K5: 1
A6: SHA | B6: Budget and BP | C6: Budget and BP Inputs & Assumptions | D6: Identify the full list of inputs and assumptions required to build the model. Define sources and providers for each item, and set deadlines for delivery. | E6: Hassen Moolla | F6: Completed | G6: =I5 -> 46068 | H6: 18 | I6: =G6+H6 -> 46086 | J6: =IFERROR(MAX(0,MIN(1,(TODAY()-G6)/(I6-G6))),"") -> 1 | K6: 1 | L6: The full list of inputs and assumptions has been identified (Maaden view) and sources and providers have been defined. Next step is to build the model.
A7: SHA | B7: Budget and BP | C7: 5-Year Exploration Plan | D7: Develop 5-year Exploration Plan (2026-2030) | E7: Owen Hatton | F7: Completed | G7: =I5 -> 46068 | H7: 18 | I7: =G7+H7 -> 46086 | J7: =IFERROR(MAX(0,MIN(1,(TODAY()-G7)/(I7-G7))),"") -> 1 | K7: 1 | L7: Working program has been prepared and approved by Maaden leadership. Granular view available for 2026 and forecast covering 2027–2030. Available to be shared upon request.
A8: SHA | B8: Budget and BP | C8: JV Day-1 Org Chart | D8: Finalize the Day-1 organization structure (confirm minimal technical staff requirements, including HSSE) | E8: Mohammed Al-Hamed | F8: Completed | G8: 46071 | H8: 14 | I8: =G8+H8 -> 46085 | J8: =IFERROR(MAX(0,MIN(1,(TODAY()-G8)/(I8-G8))),"") -> 1 | K8: 1 | L8: Day-1 organization structure has been finalized and is ready to be shared.
A9: SHA | B9: Budget and BP | C9: Build Draft BP Model | D9: Construct the financial and operational model based on the defined inputs, assumptions, and agreed structure. Ensure formulas are robust and the model is auditable. | E9: Hassen Moolla | F9: On-track | G9: =I7 -> 46086 | H9: 7 | I9: =G9+H9 -> 46093 | J9: =IFERROR(MAX(0,MIN(1,(TODAY()-G9)/(I9-G9))),"") -> 0.71428571 | K9: 0.7 | L9: Model development is currently being executed. First draft to be delivered by Maaden by 12 March 2026.
A10: SHA | B10: Budget and BP | C10: Validate BP with Key Maaden Stakeholders | D10: ². Incorporate feedback and resolve any open items. | E10: Hassen Moolla | F10: Not Started | G10: =I9 -> 46093 | H10: 3 | I10: =G10+H10 -> 46096 | J10: =IFERROR(MAX(0,MIN(1,(TODAY()-G10)/(I10-G10))),"") -> 0 | K10: 0
A11: SHA | B11: Budget and BP | C11: Align on BP template | D11: Maaden and Aramco to align on format/templates of final BP deliverables | E11: Hassen Moolla | F11: On-track | G11: 46089 | H11: 4 | I11: =G11+H11 -> 46093 | J11: =IFERROR(MAX(0,MIN(1,(TODAY()-G11)/(I11-G11))),"") -> 0.5 | K11: 0.5
A12: SHA | B12: Budget and BP | C12: Package BP into Final Deliverable | D12: Develop final BP deliverables as per template defined | E12: Hassen Moolla | F12: Not Started | G12: =I10 -> 46096 | H12: 7 | I12: =G12+H12 -> 46103 | J12: =IFERROR(MAX(0,MIN(1,(TODAY()-G12)/(I12-G12))),"") -> 0 | K12: 0
A13: SHA | B13: Budget and BP | C13: BP Final Deliverable validation | D13: Validate final deliverables | E13: Mohammed Al-Hamed | F13: Not Started | G13: =I12 -> 46103 | H13: 2 | I13: =G13+H13 -> 46105 | J13: =IFERROR(MAX(0,MIN(1,(TODAY()-G13)/(I13-G13))),"") -> 0 | K13: 0
A14: SHA | B14: Budget and BP | C14: Aramco Feedback on BP & Update | D14: Share the finalized BP with Aramco for review. Collect feedback, incorporate agreed changes, and lock the final version for approval | E14: Mohammed Al-Hamed | F14: Not Started | G14: =I13 -> 46105 | H14: 7 | I14: =G14+H14 -> 46112 | J14: =IFERROR(MAX(0,MIN(1,(TODAY()-G14)/(I14-G14))),"") -> 0 | K14: 0
B15: TSA | G15: =MIN(G16:G21) -> 46054 | H15: =I15-G15 -> 56 | I15: =MAX(I16:I21) -> 46110
A16: SHA | B16: TSA | C16: TSA Technical Services Catalogue | D16: Develop the catalogue of technical services to be provided by Maaden to the JV under the TSA, identify what services are to be provided by 3d parties | E16: Owen Hatton | F16: Completed | G16: 46054 | H16: 11 | I16: =G16+H16 -> 46065 | J16: =IFERROR(MAX(0,MIN(1,(TODAY()-G16)/(I16-G16))),"") -> 1 | K16: 1
A17: SHA | B17: TSA | C17: TSA Charge-out Rate Methodology | D17: Define the pricing methodology: establish the approach and basis for pricing each category of services (e.g., cost-plus, market benchmark, fixed fee) | E17: Hassen Moolla | F17: Completed | G17: =I16 -> 46065 | H17: 24 | I17: =G17+H17 -> 46089 | J17: =IFERROR(MAX(0,MIN(1,(TODAY()-G17)/(I17-G17))),"") -> 1 | K17: 1 | L17: Initial approach has been defined. To be reviewed and agreed with workstream leader during the week of 8–15 March 2026.
A18: SHA | B18: TSA | C18: TSA Charge-out Rates Determination | D18: Apply the agreed pricing methodology to determine the applicable rates for each service in the catalogue | E18: Hassen Moolla | F18: On-track | G18: =I17 -> 46089 | H18: 7 | I18: =G18+H18 -> 46096 | J18: =IFERROR(MAX(0,MIN(1,(TODAY()-G18)/(I18-G18))),"") -> 0.28571429 | K18: 0.3 | L18: To be initiated following review and agreement of the pricing methodology with workstream leaders. Target completion by 15 March 2026.
A19: SHA | B19: TSA | C19: TSA Governance structure | D19: Define TSA governance structure and process: how TSA services are requested, approved, monitored, billed, paid, accounted (TSA management process) | E19: Muddassar | F19: On-track | G19: 46085 | H19: 14 | I19: =G19+H19 -> 46099 | J19: =IFERROR(MAX(0,MIN(1,(TODAY()-G19)/(I19-G19))),"") -> 0.42857143 | K19: 0.3 | L19: Aramco TSA has been reviewed and comments shared with legal. On Maaden TSA, concept is being developed; first internal discussions with Maaden project leadership scheduled for early next week.
A20: SHA | B20: TSA | C20: TSA Legal framework | D20: Finalize the TSA legal framework: draft and agree on the legal terms and conditions governing the provision of services, including scope, performance standards, liability, and termination provisions | E20: Aseel Alnafea | F20: On-track | G20: 46089 | H20: 14 | I20: =G20+H20 -> 46103 | J20: =IFERROR(MAX(0,MIN(1,(TODAY()-G20)/(I20-G20))),"") -> 0.14285714 | K20: 0.15
A21: SHA | B21: TSA | C21: Aramco Feedback on TSA & Update | D21: Share the finalized TSA version with Aramco for review. Collect feedback, incorporate agreed changes, and lock the final version for approval. | E21: Muddassar Khan | F21: Not Started | G21: =I20 -> 46103 | H21: 7 | I21: =G21+H21 -> 46110 | J21: =IFERROR(MAX(0,MIN(1,(TODAY()-G21)/(I21-G21))),"") -> 0 | K21: 0
B22: GSA | G22: =MIN(G23:G28) -> 46054 | H22: =I22-G22 -> 56 | I22: =MAX(I23:I28) -> 46110
A23: SHA | B23: GSA | C23: GSA Catalogue of services | D23: Develop the catalogue of services to be provided by Maaden to the JV under the GSA | E23: Hassen Moolla | F23: Delayed | G23: 46054 | H23: 35 | I23: =G23+H23 -> 46089 | J23: =IFERROR(MAX(0,MIN(1,(TODAY()-G23)/(I23-G23))),"") -> 1 | K23: 0.8 | L23: Catalogue has been developed and partially validated by workstream leaders. Target to finalise validation by 10 March 2026.
A24: SHA | B24: GSA | C24: GSA Charge-out Rate Methodology | D24: Define the pricing methodology: establish the approach and basis for pricing each category of services (e.g., cost-plus, market benchmark, fixed fee) | E24: Hassen Moolla | F24: On-track | G24: 46069 | H24: 24 | I24: =G24+H24 -> 46093 | J24: =IFERROR(MAX(0,MIN(1,(TODAY()-G24)/(I24-G24))),"") -> 0.91666667 | K24: 0.8 | L24: Initial approach has been defined. To be reviewed and agreed with workstream leaders during the week of 8–15 March 2026.
A25: SHA | B25: GSA | C25: GSA Charge-out Rates Determination | D25: Apply the agreed pricing methodology to determine the applicable rates for each service in the catalogue | E25: Hassen Moolla | F25: Not Started | G25: =I24 -> 46093 | H25: 7 | I25: =G25+H25 -> 46100 | J25: =IFERROR(MAX(0,MIN(1,(TODAY()-G25)/(I25-G25))),"") -> 0 | K25: 0
A26: SHA | B26: GSA | C26: GSA Governance structure | D26: Define GSA governance structure and process : how GSA services are requested, approved, monitored, billed, paid, accounted (GSA management process) | E26: Muddassar | F26: On-track | G26: 46085 | H26: 14 | I26: =G26+H26 -> 46099 | J26: =IFERROR(MAX(0,MIN(1,(TODAY()-G26)/(I26-G26))),"") -> 0.42857143 | K26: 0.3 | L26: On Maaden GSA, concept is being developed; first internal discussions with Maaden project leadership scheduled for early next week.
A27: SHA | B27: GSA | C27: GSA Legal framework | D27: Finalize the GSA legal framework: draft and agree on the legal terms and conditions governing the provision of services, including scope, performance standards, liability, and termination provisions | E27: Aseel Alnafea | F27: On-track | G27: 46089 | H27: 14 | I27: =G27+H27 -> 46103 | J27: =IFERROR(MAX(0,MIN(1,(TODAY()-G27)/(I27-G27))),"") -> 0.14285714 | K27: 0.15
A28: SHA | B28: GSA | C28: Aramco Feedback on GSA & Update | D28: Share the finalized TSA version with Aramco for review. Collect feedback, incorporate agreed changes, and lock the final version for approval | E28: Muddassar Khan | F28: Not Started | G28: =I27 -> 46103 | H28: 7 | I28: =G28+H28 -> 46110 | J28: =IFERROR(MAX(0,MIN(1,(TODAY()-G28)/(I28-G28))),"") -> 0 | K28: 0 | L28: STILL OPEN. Schedule 13 is completely empty. Each party needs to disclose their existing competing businesses. This is referenced in Clause 20.1(a)(i).STILL OPEN. Schedule 14 is completely empty. The funding notice templates need to be developed. Plus, the distinction between 'Form of Funding Notices' and 'Funding Request Notice template' is unclear in the SHA.
B29: DoA | G29: =MIN(G30:G32) -> 46068 | H29: =I29-G29 -> 37 | I29: =MAX(I30:I32) -> 46105
A30: SHA | B30: DoA | C30: Shareholders DoAs reference | D30: Obtain reference governance framework, obtain Maaden's existing Authority Matrix and Aramco's governance frameworks as benchmarks for the JV | E30: Mawiyah Alqaed | F30: Completed | G30: 46077 | H30: 9 | I30: =G30+H30 -> 46086 | J30: =IFERROR(MAX(0,MIN(1,(TODAY()-G30)/(I30-G30))),"") -> 1 | K30: 1
A31: SHA | B31: DoA | C31: Complete Design of DoA (Shedule 15) | D31: Design the multi-tiered financial approval matrix (incl governance and internal controls) : define approval tiers below Board thresholds across CAPEX, OPEX, contracts, procurement, HR, litigation, treasury, and asset management, aligned with SHA | E31: Omar Jabart | F31: On-track | G31: 46068 | H31: 30 | I31: =G31+H31 -> 46098 | J31: =IFERROR(MAX(0,MIN(1,(TODAY()-G31)/(I31-G31))),"") -> 0.76666667 | K31: 0.8 | L31: Mar 9th: Draft prepared; under review by Effat
A32: SHA | B32: DoA | C32: Aramco Feedback on DoA & Update | D32: Share the finalized DoA version with Aramco for review. Collect feedback, incorporate agreed changes, and lock the final version for approval | E32: Muddassar/ Mohammed | F32: Not Started | G32: =I31 -> 46098 | H32: 7 | I32: =G32+H32 -> 46105 | J32: =IFERROR(MAX(0,MIN(1,(TODAY()-G32)/(I32-G32))),"") -> 0 | K32: 0
B33: Secondment | G33: =MIN(G34:G37) -> 46054 | H33: =I33-G33 -> 62 | I33: =MAX(I34:I37) -> 46116
A34: SHA | B34: Secondment | C34: Secondment framework | D34: Develop secondment framework agreement (duration, cost basis, reporting lines, benefits) | E34: Rene Thumbran | F34: On-track | G34: 46054 | H34: 40 | I34: =G34+H34 -> 46094 | J34: =IFERROR(MAX(0,MIN(1,(TODAY()-G34)/(I34-G34))),"") -> 0.925 | K34: 0.8 | L34: Standard master framework
A35: SHA | B35: Secondment | C35: Secondment Agreement Allocation Methodology | D35: Define cost allocation methodology and determine cost rates for secondees | E35: Rene Thumbran | F35: On-track | G35: 46055 | H35: 40 | I35: =G35+H35 -> 46095 | J35: =IFERROR(MAX(0,MIN(1,(TODAY()-G35)/(I35-G35))),"") -> 0.9 | K35: 0.8
A36: SHA | B36: Secondment | C36: JV Secondment Agreement draft | D36: Draft JV secondment agreement | E36: Aseel Alnafea | F36: Not Started | G36: =I35 -> 46095 | H36: 14 | I36: =G36+H36 -> 46109 | J36: =IFERROR(MAX(0,MIN(1,(TODAY()-G36)/(I36-G36))),"") -> 0 | K36: 0 | L36: with support of Rene Thumbran
A37: SHA | B37: Secondment | C37: Aramco Feedback on Secondment Agreement & Update | D37: Share the finalized Secondment Agreement with Aramco for review. Collect feedback, incorporate agreed changes, and lock the final version for approval | E37: Muddassar/ Mohammed | F37: Not Started | G37: =I36 -> 46109 | H37: 7 | I37: =G37+H37 -> 46116 | J37: =IFERROR(MAX(0,MIN(1,(TODAY()-G37)/(I37-G37))),"") -> 0 | K37: 0
B38: SHA documentation | G38: =MIN(G39:G46) -> 46072 | H38: =I38-G38 -> 62 | I38: =MAX(I39:I46) -> 46134
A39: SHA | B39: SHA documentation | C39: SHA Sch.11 Guarantee for Permitted Transfers | D39: Agree Form of Guarantee for Permitted Transfers (Schedule 11) | E39: Muddassar Khan | F39: On-track | G39: 46072 | H39: 20 | I39: =G39+H39 -> 46092 | J39: =IFERROR(MAX(0,MIN(1,(TODAY()-G39)/(I39-G39))),"") -> 0.95
A40: SHA | B40: SHA documentation | C40: SHA Sch.12 Form of the Agreement | D40: Finalize Form of Shareholder Services Agreement (Schedule 12) | E40: Muddassar Khan | F40: Not Started | G40: =I26 -> 46099 | H40: 7 | I40: =G40+H40 -> 46106 | J40: =IFERROR(MAX(0,MIN(1,(TODAY()-G40)/(I40-G40))),"") -> 0 | L40: STILL OPEN. What exactly is this form? We understand GSA is a separament document, correct?
A41: SHA | B41: SHA documentation | C41: SHA Sch.14 Competing business disclosure | D41: Complete existing competing businesses disclosure (Schedule 14) (action also required for aramco) | E41: Aseel Alnafea | F41: On-track | G41: 46077 | H41: 14 | I41: =G41+H41 -> 46091 | J41: =IFERROR(MAX(0,MIN(1,(TODAY()-G41)/(I41-G41))),"") -> 1 | L41: STILL OPEN. Schedule 13 is completely empty. Each party needs to disclose their existing competing businesses. This is referenced in Clause 20.1(a)(i).
...

Sheet Pivot Table
A3: Count of Action | B3: Column Labels
A4: Row Labels | B4: Not Started | C4: On-track | D4: Completed | E4: Delayed | F4: Grand Total
A5: Corporate Governance Setup | B5: 5 | F5: 5
A6: Governance | B6: 5 | F6: 5
A7: Entity Formation | B7: 18 | D7: 1 | F7: 19
A8: Governance | B8: 14 | D8: 1 | F8: 15
A9: Legal | B9: 4 | F9: 4
A10: Operational readiness | B10: 35 | C10: 4 | D10: 1 | F10: 40
A11: IT | B11: 11 | C11: 1 | D11: 1 | F11: 13
A12: Finance | B12: 10 | F12: 10
A13: HSSE | B13: 4 | C13: 1 | F13: 5
A14: Procurement | B14: 3 | C14: 1 | F14: 4
A15: HR | B15: 3 | C15: 1 | F15: 4
A16: Comms | B16: 3 | F16: 3
A17: Facilities | B17: 1 | F17: 1
A18: Post-formation registration | B18: 9 | F18: 9
A19: GR | B19: 4 | F19: 4
A20: Legal | B20: 2 | F20: 2
A21: HR | B21: 2 | F21: 2
A22: HSSE | B22: 1 | F22: 1
A23: SHA | B23: 14 | C23: 19 | D23: 12 | E23: 1 | F23: 46
A24: Budget and BP | B24: 4 | C24: 2 | D24: 4 | F24: 10
A25: Corporate approval | B25: 2 | C25: 2 | D25: 5 | F25: 9
A26: SHA documentation | B26: 2 | C26: 6 | F26: 8
A27: TSA | B27: 1 | C27: 3 | D27: 2 | F27: 6
A28: GSA | B28: 2 | C28: 3 | E28: 1 | F28: 6
A29: Secondment | B29: 2 | C29: 2 | F29: 4
A30: DoA | B30: 1 | C30: 1 | D30: 1 | F30: 3
A31: Grand Total | B31: 81 | C31: 23 | D31: 14 | E31: 1 | F31: 119

Sheet Data Validation List
A1: Critical | B1: Status
A2: Yes | B2: Not Started
A3: No | B3: Delayed
B4: On-track
B5: Completed
