Workbook
Name POWER_USER_LINK_EDA81D4C_E424_4C6E_8A36_5F1A4994EB75: "Summary!R4C1:R17C2"

Sheet Cover
C7: Title | D7: Project Crystal - JV Day 1 Readiness Plan
C9: Description | D9: All actions required to achieve JV Day-1 operational readiness
C11: Date | D11: =TODAY() -> 46083

Sheet Summary
B2: REQUIREMENTS BY OWNER | C2: =SUM(C4:C28) -> 117 | D2: =SUM(D4:D28) -> 4 | E2: =SUM(E4:E28) -> 89 | F2: =SUM(F4:F28) -> 24 | G2: =SUM(G4:G28) -> 0 | I2: REQUIREMENTS BY CATEGORY | J2: =SUM(J4:J20) -> 119 | K2: =SUM(K4:K20) -> 4 | L2: =SUM(L4:L20) -> 91 | M2: =SUM(M4:M20) -> 24 | N2: =SUM(N4:N20) -> 0
B3: Owner | C3: Total | D3: Completed | E3: Not started | F3: On-track | G3: Delayed | I3: Workstream | J3: Total | K3: Completed | L3: Not started | M3: On-track | N3: Delayed
B4: Hassen Moolla | C4: =SUM(D4:G4) -> 16 | D4: =(COUNTIFS('JV Readiness Plan'!$E:$E,$B4,'JV Readiness Plan'!$F:$F,D$3)) -> 1 | E4: =(COUNTIFS('JV Readiness Plan'!$E:$E,$B4,'JV Readiness Plan'!$F:$F,E$3)) -> 9 | F4: =(COUNTIFS('JV Readiness Plan'!$E:$E,$B4,'JV Readiness Plan'!$F:$F,F$3)) -> 6 | G4: =(COUNTIFS('JV Readiness Plan'!$E:$E,$B4,'JV Readiness Plan'!$F:$F,G$3)) -> 0 | I4: Budget and BP | J4: =SUM(K4:N4) -> 9 | K4: =(COUNTIFS('JV Readiness Plan'!$B:$B,$I4,'JV Readiness Plan'!$F:$F,K$3)) -> 1 | L4: =(COUNTIFS('JV Readiness Plan'!$B:$B,$I4,'JV Readiness Plan'!$F:$F,L$3)) -> 4 | M4: =(COUNTIFS('JV Readiness Plan'!$B:$B,$I4,'JV Readiness Plan'!$F:$F,M$3)) -> 4 | N4: =(COUNTIFS('JV Readiness Plan'!$B:$B,$I4,'JV Readiness Plan'!$F:$F,N$3)) -> 0
B5: Muddassar Khan | C5: =SUM(D5:G5) -> 14 | D5: =(COUNTIFS('JV Readiness Plan'!$E:$E,$B5,'JV Readiness Plan'!$F:$F,D$3)) -> 2 | E5: =(COUNTIFS('JV Readiness Plan'!$E:$E,$B5,'JV Readiness Plan'!$F:$F,E$3)) -> 5 | F5: =(COUNTIFS('JV Readiness Plan'!$E:$E,$B5,'JV Readiness Plan'!$F:$F,F$3)) -> 7 | G5: =(COUNTIFS('JV Readiness Plan'!$E:$E,$B5,'JV Readiness Plan'!$F:$F,G$3)) -> 0 | I5: TSA | J5: =SUM(K5:N5) -> 6 | K5: =(COUNTIFS('JV Readiness Plan'!$B:$B,$I5,'JV Readiness Plan'!$F:$F,K$3)) -> 1 | L5: =(COUNTIFS('JV Readiness Plan'!$B:$B,$I5,'JV Readiness Plan'!$F:$F,L$3)) -> 4 | M5: =(COUNTIFS('JV Readiness Plan'!$B:$B,$I5,'JV Readiness Plan'!$F:$F,M$3)) -> 1 | N5: =(COUNTIFS('JV Readiness Plan'!$B:$B,$I5,'JV Readiness Plan'!$F:$F,N$3)) -> 0
B6: Ramesh Murugesan | C6: =SUM(D6:G6) -> 13 | D6: =(COUNTIFS('JV Readiness Plan'!$E:$E,$B6,'JV Readiness Plan'!$F:$F,D$3)) -> 0 | E6: =(COUNTIFS('JV Readiness Plan'!$E:$E,$B6,'JV Readiness Plan'!$F:$F,E$3)) -> 12 | F6: =(COUNTIFS('JV Readiness Plan'!$E:$E,$B6,'JV Readiness Plan'!$F:$F,F$3)) -> 1 | G6: =(COUNTIFS('JV Readiness Plan'!$E:$E,$B6,'JV Readiness Plan'!$F:$F,G$3)) -> 0 | I6: GSA | J6: =SUM(K6:N6) -> 6 | K6: =(COUNTIFS('JV Readiness Plan'!$B:$B,$I6,'JV Readiness Plan'!$F:$F,K$3)) -> 0 | L6: =(COUNTIFS('JV Readiness Plan'!$B:$B,$I6,'JV Readiness Plan'!$F:$F,L$3)) -> 4 | M6: =(COUNTIFS('JV Readiness Plan'!$B:$B,$I6,'JV Readiness Plan'!$F:$F,M$3)) -> 2 | N6: =(COUNTIFS('JV Readiness Plan'!$B:$B,$I6,'JV Readiness Plan'!$F:$F,N$3)) -> 0
B7: Mawiyah Alqaed | C7: =SUM(D7:G7) -> 11 | D7: =(COUNTIFS('JV Readiness Plan'!$E:$E,$B7,'JV Readiness Plan'!$F:$F,D$3)) -> 0 | E7: =(COUNTIFS('JV Readiness Plan'!$E:$E,$B7,'JV Readiness Plan'!$F:$F,E$3)) -> 9 | F7: =(COUNTIFS('JV Readiness Plan'!$E:$E,$B7,'JV Readiness Plan'!$F:$F,F$3)) -> 2 | G7: =(COUNTIFS('JV Readiness Plan'!$E:$E,$B7,'JV Readiness Plan'!$F:$F,G$3)) -> 0 | I7: DoA | J7: =SUM(K7:N7) -> 3 | K7: =(COUNTIFS('JV Readiness Plan'!$B:$B,$I7,'JV Readiness Plan'!$F:$F,K$3)) -> 0 | L7: =(COUNTIFS('JV Readiness Plan'!$B:$B,$I7,'JV Readiness Plan'!$F:$F,L$3)) -> 1 | M7: =(COUNTIFS('JV Readiness Plan'!$B:$B,$I7,'JV Readiness Plan'!$F:$F,M$3)) -> 2 | N7: =(COUNTIFS('JV Readiness Plan'!$B:$B,$I7,'JV Readiness Plan'!$F:$F,N$3)) -> 0
B8: Aseel Alnafea | C8: =SUM(D8:G8) -> 8 | D8: =(COUNTIFS('JV Readiness Plan'!$E:$E,$B8,'JV Readiness Plan'!$F:$F,D$3)) -> 0 | E8: =(COUNTIFS('JV Readiness Plan'!$E:$E,$B8,'JV Readiness Plan'!$F:$F,E$3)) -> 7 | F8: =(COUNTIFS('JV Readiness Plan'!$E:$E,$B8,'JV Readiness Plan'!$F:$F,F$3)) -> 1 | G8: =(COUNTIFS('JV Readiness Plan'!$E:$E,$B8,'JV Readiness Plan'!$F:$F,G$3)) -> 0 | I8: Secondment | J8: =SUM(K8:N8) -> 4 | K8: =(COUNTIFS('JV Readiness Plan'!$B:$B,$I8,'JV Readiness Plan'!$F:$F,K$3)) -> 0 | L8: =(COUNTIFS('JV Readiness Plan'!$B:$B,$I8,'JV Readiness Plan'!$F:$F,L$3)) -> 2 | M8: =(COUNTIFS('JV Readiness Plan'!$B:$B,$I8,'JV Readiness Plan'!$F:$F,M$3)) -> 2 | N8: =(COUNTIFS('JV Readiness Plan'!$B:$B,$I8,'JV Readiness Plan'!$F:$F,N$3)) -> 0
B9: Rene Thumbran | C9: =SUM(D9:G9) -> 7 | D9: =(COUNTIFS('JV Readiness Plan'!$E:$E,$B9,'JV Readiness Plan'!$F:$F,D$3)) -> 0 | E9: =(COUNTIFS('JV Readiness Plan'!$E:$E,$B9,'JV Readiness Plan'!$F:$F,E$3)) -> 5 | F9: =(COUNTIFS('JV Readiness Plan'!$E:$E,$B9,'JV Readiness Plan'!$F:$F,F$3)) -> 2 | G9: =(COUNTIFS('JV Readiness Plan'!$E:$E,$B9,'JV Readiness Plan'!$F:$F,G$3)) -> 0 | I9: SHA documentation | J9: =SUM(K9:N9) -> 9 | K9: =(COUNTIFS('JV Readiness Plan'!$B:$B,$I9,'JV Readiness Plan'!$F:$F,K$3)) -> 0 | L9: =(COUNTIFS('JV Readiness Plan'!$B:$B,$I9,'JV Readiness Plan'!$F:$F,L$3)) -> 1 | M9: =(COUNTIFS('JV Readiness Plan'!$B:$B,$I9,'JV Readiness Plan'!$F:$F,M$3)) -> 8 | N9: =(COUNTIFS('JV Readiness Plan'!$B:$B,$I9,'JV Readiness Plan'!$F:$F,N$3)) -> 0
B10: Mohammed Al-Hamed | C10: =SUM(D10:G10) -> 6 | D10: =(COUNTIFS('JV Readiness Plan'!$E:$E,$B10,'JV Readiness Plan'!$F:$F,D$3)) -> 0 | E10: =(COUNTIFS('JV Readiness Plan'!$E:$E,$B10,'JV Readiness Plan'!$F:$F,E$3)) -> 4 | F10: =(COUNTIFS('JV Readiness Plan'!$E:$E,$B10,'JV Readiness Plan'!$F:$F,F$3)) -> 2 | G10: =(COUNTIFS('JV Readiness Plan'!$E:$E,$B10,'JV Readiness Plan'!$F:$F,G$3)) -> 0 | I10: Corporate approval | J10: =SUM(K10:N10) -> 9 | K10: =(COUNTIFS('JV Readiness Plan'!$B:$B,$I10,'JV Readiness Plan'!$F:$F,K$3)) -> 2 | L10: =(COUNTIFS('JV Readiness Plan'!$B:$B,$I10,'JV Readiness Plan'!$F:$F,L$3)) -> 5 | M10: =(COUNTIFS('JV Readiness Plan'!$B:$B,$I10,'JV Readiness Plan'!$F:$F,M$3)) -> 2 | N10: =(COUNTIFS('JV Readiness Plan'!$B:$B,$I10,'JV Readiness Plan'!$F:$F,N$3)) -> 0
B11: Faraj Al Dossary | C11: =SUM(D11:G11) -> 6 | D11: =(COUNTIFS('JV Readiness Plan'!$E:$E,$B11,'JV Readiness Plan'!$F:$F,D$3)) -> 0 | E11: =(COUNTIFS('JV Readiness Plan'!$E:$E,$B11,'JV Readiness Plan'!$F:$F,E$3)) -> 6 | F11: =(COUNTIFS('JV Readiness Plan'!$E:$E,$B11,'JV Readiness Plan'!$F:$F,F$3)) -> 0 | G11: =(COUNTIFS('JV Readiness Plan'!$E:$E,$B11,'JV Readiness Plan'!$F:$F,G$3)) -> 0 | I11: Governance | J11: =SUM(K11:N11) -> 20 | K11: =(COUNTIFS('JV Readiness Plan'!$B:$B,$I11,'JV Readiness Plan'!$F:$F,K$3)) -> 0 | L11: =(COUNTIFS('JV Readiness Plan'!$B:$B,$I11,'JV Readiness Plan'!$F:$F,L$3)) -> 18 | M11: =(COUNTIFS('JV Readiness Plan'!$B:$B,$I11,'JV Readiness Plan'!$F:$F,M$3)) -> 2 | N11: =(COUNTIFS('JV Readiness Plan'!$B:$B,$I11,'JV Readiness Plan'!$F:$F,N$3)) -> 0
B12: Omar Jabart | C12: =SUM(D12:G12) -> 6 | D12: =(COUNTIFS('JV Readiness Plan'!$E:$E,$B12,'JV Readiness Plan'!$F:$F,D$3)) -> 0 | E12: =(COUNTIFS('JV Readiness Plan'!$E:$E,$B12,'JV Readiness Plan'!$F:$F,E$3)) -> 4 | F12: =(COUNTIFS('JV Readiness Plan'!$E:$E,$B12,'JV Readiness Plan'!$F:$F,F$3)) -> 2 | G12: =(COUNTIFS('JV Readiness Plan'!$E:$E,$B12,'JV Readiness Plan'!$F:$F,G$3)) -> 0 | I12: Legal | J12: =SUM(K12:N12) -> 6 | K12: =(COUNTIFS('JV Readiness Plan'!$B:$B,$I12,'JV Readiness Plan'!$F:$F,K$3)) -> 0 | L12: =(COUNTIFS('JV Readiness Plan'!$B:$B,$I12,'JV Readiness Plan'!$F:$F,L$3)) -> 6 | M12: =(COUNTIFS('JV Readiness Plan'!$B:$B,$I12,'JV Readiness Plan'!$F:$F,M$3)) -> 0 | N12: =(COUNTIFS('JV Readiness Plan'!$B:$B,$I12,'JV Readiness Plan'!$F:$F,N$3)) -> 0
B13: Abdulrahman Abdullah Al-zahrani | C13: =SUM(D13:G13) -> 4 | D13: =(COUNTIFS('JV Readiness Plan'!$E:$E,$B13,'JV Readiness Plan'!$F:$F,D$3)) -> 0 | E13: =(COUNTIFS('JV Readiness Plan'!$E:$E,$B13,'JV Readiness Plan'!$F:$F,E$3)) -> 4 | F13: =(COUNTIFS('JV Readiness Plan'!$E:$E,$B13,'JV Readiness Plan'!$F:$F,F$3)) -> 0 | G13: =(COUNTIFS('JV Readiness Plan'!$E:$E,$B13,'JV Readiness Plan'!$F:$F,G$3)) -> 0 | I13: GR | J13: =SUM(K13:N13) -> 4 | K13: =(COUNTIFS('JV Readiness Plan'!$B:$B,$I13,'JV Readiness Plan'!$F:$F,K$3)) -> 0 | L13: =(COUNTIFS('JV Readiness Plan'!$B:$B,$I13,'JV Readiness Plan'!$F:$F,L$3)) -> 4 | M13: =(COUNTIFS('JV Readiness Plan'!$B:$B,$I13,'JV Readiness Plan'!$F:$F,M$3)) -> 0 | N13: =(COUNTIFS('JV Readiness Plan'!$B:$B,$I13,'JV Readiness Plan'!$F:$F,N$3)) -> 0
B14: Fathima Mahomed | C14: =SUM(D14:G14) -> 4 | D14: =(COUNTIFS('JV Readiness Plan'!$E:$E,$B14,'JV Readiness Plan'!$F:$F,D$3)) -> 0 | E14: =(COUNTIFS('JV Readiness Plan'!$E:$E,$B14,'JV Readiness Plan'!$F:$F,E$3)) -> 4 | F14: =(COUNTIFS('JV Readiness Plan'!$E:$E,$B14,'JV Readiness Plan'!$F:$F,F$3)) -> 0 | G14: =(COUNTIFS('JV Readiness Plan'!$E:$E,$B14,'JV Readiness Plan'!$F:$F,G$3)) -> 0 | I14: HR | J14: =SUM(K14:N14) -> 6 | K14: =(COUNTIFS('JV Readiness Plan'!$B:$B,$I14,'JV Readiness Plan'!$F:$F,K$3)) -> 0 | L14: =(COUNTIFS('JV Readiness Plan'!$B:$B,$I14,'JV Readiness Plan'!$F:$F,L$3)) -> 6 | M14: =(COUNTIFS('JV Readiness Plan'!$B:$B,$I14,'JV Readiness Plan'!$F:$F,M$3)) -> 0 | N14: =(COUNTIFS('JV Readiness Plan'!$B:$B,$I14,'JV Readiness Plan'!$F:$F,N$3)) -> 0
B15: Muddassar/Mohammed | C15: =SUM(D15:G15) -> 3 | D15: =(COUNTIFS('JV Readiness Plan'!$E:$E,$B15,'JV Readiness Plan'!$F:$F,D$3)) -> 0 | E15: =(COUNTIFS('JV Readiness Plan'!$E:$E,$B15,'JV Readiness Plan'!$F:$F,E$3)) -> 3 | F15: =(COUNTIFS('JV Readiness Plan'!$E:$E,$B15,'JV Readiness Plan'!$F:$F,F$3)) -> 0 | G15: =(COUNTIFS('JV Readiness Plan'!$E:$E,$B15,'JV Readiness Plan'!$F:$F,G$3)) -> 0 | I15: HSSE | J15: =SUM(K15:N15) -> 6 | K15: =(COUNTIFS('JV Readiness Plan'!$B:$B,$I15,'JV Readiness Plan'!$F:$F,K$3)) -> 0 | L15: =(COUNTIFS('JV Readiness Plan'!$B:$B,$I15,'JV Readiness Plan'!$F:$F,L$3)) -> 6 | M15: =(COUNTIFS('JV Readiness Plan'!$B:$B,$I15,'JV Readiness Plan'!$F:$F,M$3)) -> 0 | N15: =(COUNTIFS('JV Readiness Plan'!$B:$B,$I15,'JV Readiness Plan'!$F:$F,N$3)) -> 0
... B20: Abdullah Alzamil | C20: =SUM(D20:G20) -> 2 | D20: =(COUNTIFS('JV Readiness Plan'!$E:$E,$B20,'JV Readiness Plan'!$F:$F,D$3)) -> 0 | E20: =(COUNTIFS('JV Readiness Plan'!$E:$E,$B20,'JV Readiness Plan'!$F:$F,E$3)) -> 2 | F20: =(COUNTIFS('JV Readiness Plan'!$E:$E,$B20,'JV Readiness Plan'!$F:$F,F$3)) -> 0 | G20: =(COUNTIFS('JV Readiness Plan'!$E:$E,$B20,'JV Readiness Plan'!$F:$F,G$3)) -> 0 | I20: Facilities | J20: =SUM(K20:N20) -> 1 | K20: =(COUNTIFS('JV Readiness Plan'!$B:$B,$I20,'JV Readiness Plan'!$F:$F,K$3)) -> 0 | L20: =(COUNTIFS('JV Readiness Plan'!$B:$B,$I20,'JV Readiness Plan'!$F:$F,L$3)) -> 1 | M20: =(COUNTIFS('JV Readiness Plan'!$B:$B,$I20,'JV Readiness Plan'!$F:$F,M$3)) -> 0 | N20: =(COUNTIFS('JV Readiness Plan'!$B:$B,$I20,'JV Readiness Plan'!$F:$F,N$3)) -> 0
B21: Karim Mehboob | C21: =SUM(D21:G21) -> 2 | D21: =(COUNTIFS('JV Readiness Plan'!$E:$E,$B21,'JV Readiness Plan'!$F:$F,D$3)) -> 0 | E21: =(COUNTIFS('JV Readiness Plan'!$E:$E,$B21,'JV Readiness Plan'!$F:$F,E$3)) -> 2 | F21: =(COUNTIFS('JV Readiness Plan'!$E:$E,$B21,'JV Readiness Plan'!$F:$F,F$3)) -> 0 | G21: =(COUNTIFS('JV Readiness Plan'!$E:$E,$B21,'JV Readiness Plan'!$F:$F,G$3)) -> 0
B22: Marwan Sutan | C22: =SUM(D22:G22) -> 2 | D22: =(COUNTIFS('JV Readiness Plan'!$E:$E,$B22,'JV Readiness Plan'!$F:$F,D$3)) -> 0 | E22: =(COUNTIFS('JV Readiness Plan'!$E:$E,$B22,'JV Readiness Plan'!$F:$F,E$3)) -> 2 | F22: =(COUNTIFS('JV Readiness Plan'!$E:$E,$B22,'JV Readiness Plan'!$F:$F,F$3)) -> 0 | G22: =(COUNTIFS('JV Readiness Plan'!$E:$E,$B22,'JV Readiness Plan'!$F:$F,G$3)) -> 0
B23: Ramesh / Alex | C23: =SUM(D23:G23) -> 0 | D23: =(COUNTIFS('JV Readiness Plan'!$E:$E,$B23,'JV Readiness Plan'!$F:$F,D$3)) -> 0 | E23: =(COUNTIFS('JV Readiness Plan'!$E:$E,$B23,'JV Readiness Plan'!$F:$F,E$3)) -> 0 | F23: =(COUNTIFS('JV Readiness Plan'!$E:$E,$B23,'JV Readiness Plan'!$F:$F,F$3)) -> 0 | G23: =(COUNTIFS('JV Readiness Plan'!$E:$E,$B23,'JV Readiness Plan'!$F:$F,G$3)) -> 0
B24: Aramco | C24: =SUM(D24:G24) -> 2 | D24: =(COUNTIFS('JV Readiness Plan'!$E:$E,$B24,'JV Readiness Plan'!$F:$F,D$3)) -> 0 | E24: =(COUNTIFS('JV Readiness Plan'!$E:$E,$B24,'JV Readiness Plan'!$F:$F,E$3)) -> 2 | F24: =(COUNTIFS('JV Readiness Plan'!$E:$E,$B24,'JV Readiness Plan'!$F:$F,F$3)) -> 0 | G24: =(COUNTIFS('JV Readiness Plan'!$E:$E,$B24,'JV Readiness Plan'!$F:$F,G$3)) -> 0
B25: AshLaw | C25: =SUM(D25:G25) -> 1 | D25: =(COUNTIFS('JV Readiness Plan'!$E:$E,$B25,'JV Readiness Plan'!$F:$F,D$3)) -> 0 | E25: =(COUNTIFS('JV Readiness Plan'!$E:$E,$B25,'JV Readiness Plan'!$F:$F,E$3)) -> 1 | F25: =(COUNTIFS('JV Readiness Plan'!$E:$E,$B25,'JV Readiness Plan'!$F:$F,F$3)) -> 0 | G25: =(COUNTIFS('JV Readiness Plan'!$E:$E,$B25,'JV Readiness Plan'!$F:$F,G$3)) -> 0
B26: Raud Alsuwailem | C26: =SUM(D26:G26) -> 1 | D26: =(COUNTIFS('JV Readiness Plan'!$E:$E,$B26,'JV Readiness Plan'!$F:$F,D$3)) -> 0 | E26: =(COUNTIFS('JV Readiness Plan'!$E:$E,$B26,'JV Readiness Plan'!$F:$F,E$3)) -> 1 | F26: =(COUNTIFS('JV Readiness Plan'!$E:$E,$B26,'JV Readiness Plan'!$F:$F,F$3)) -> 0 | G26: =(COUNTIFS('JV Readiness Plan'!$E:$E,$B26,'JV Readiness Plan'!$F:$F,G$3)) -> 0
B27: Governance Dept | C27: =SUM(D27:G27) -> 1 | D27: =(COUNTIFS('JV Readiness Plan'!$E:$E,$B27,'JV Readiness Plan'!$F:$F,D$3)) -> 0 | E27: =(COUNTIFS('JV Readiness Plan'!$E:$E,$B27,'JV Readiness Plan'!$F:$F,E$3)) -> 1 | F27: =(COUNTIFS('JV Readiness Plan'!$E:$E,$B27,'JV Readiness Plan'!$F:$F,F$3)) -> 0 | G27: =(COUNTIFS('JV Readiness Plan'!$E:$E,$B27,'JV Readiness Plan'!$F:$F,G$3)) -> 0
B28: Raoof Madathil | C28: =SUM(D28:G28) -> 1 | D28: =(COUNTIFS('JV Readiness Plan'!$E:$E,$B28,'JV Readiness Plan'!$F:$F,D$3)) -> 0 | E28: =(COUNTIFS('JV Readiness Plan'!$E:$E,$B28,'JV Readiness Plan'!$F:$F,E$3)) -> 1 | F28: =(COUNTIFS('JV Readiness Plan'!$E:$E,$B28,'JV Readiness Plan'!$F:$F,F$3)) -> 0 | G28: =(COUNTIFS('JV Readiness Plan'!$E:$E,$B28,'JV Readiness Plan'!$F:$F,G$3)) -> 0

Sheet JV Readiness Plan
A1: PROJECT CRYSTAL - JV DAY-1 READINESS PLAN | H1: Day-1 target date | I1: =MAX(I4:I133) -> 46265
A3: Workstream | B3: Category | C3: Requirement | D3: Action | E3: Owner | F3: Status | G3: Start date | H3: Duration | I3: End date | J3: Target Completion (%) | K3: Actual Completion (%)
B4: Budget and Business Plan | G4: =MIN(G5:G13) -> 46054 | H4: =I4-G4 -> 58 | I4: =MAX(I5:I13) -> 46112
A5: SHA | B5: Budget and BP | C5: Budget & BP Roles & Data Sources | D5: Clarify roles and responsibilities across Maaden finance and technical teams. Define who provides what, sources of information, and internal points of contact for each workstream. | E5: Hassen Moolla | F5: Completed | G5: 46054 | H5: 14 | I5: =G5+H5 -> 46068 | J5: =IFERROR(MAX(0,MIN(1,(TODAY()-G5)/(I5-G5))),"") -> 1 | K5: 1
A6: SHA | B6: Budget and BP | C6: Budget and BP Inputs & Assumptions | D6: Identify the full list of inputs and assumptions required to build the model. Define sources and providers for each item, and set deadlines for delivery. | E6: Hassen Moolla | F6: On-track | G6: =I5 -> 46068 | H6: 18 | I6: =G6+H6 -> 46086 | J6: =IFERROR(MAX(0,MIN(1,(TODAY()-G6)/(I6-G6))),"") -> 0.83333333 | K6: 0.8
A7: SHA | B7: Budget and BP | C7: 5-Year Exploration Plan | D7: Develop 5-year Exploration Plan (2026-2030) | E7: Owen Hatton | F7: On-track | G7: =I5 -> 46068 | H7: 18 | I7: =G7+H7 -> 46086 | J7: =IFERROR(MAX(0,MIN(1,(TODAY()-G7)/(I7-G7))),"") -> 0.83333333 | K7: 0.8
A8: SHA | B8: Budget and BP | C8: JV Day-1 Org Chart | D8: Finalize the Day-1 organization structure (confirm minimal technical staff requirements, including HSSE) | E8: Mohammed Al-Hamed | F8: On-track | G8: 46071 | H8: 14 | I8: =G8+H8 -> 46085 | J8: =IFERROR(MAX(0,MIN(1,(TODAY()-G8)/(I8-G8))),"") -> 0.85714286 | K8: 0.5
A9: SHA | B9: Budget and BP | C9: Build Draft BP Model | D9: Construct the financial and operational model based on the defined inputs, assumptions, and agreed structure. Ensure formulas are robust and the model is auditable. | E9: Hassen Moolla | F9: On-track | G9: =I7 -> 46086 | H9: 7 | I9: =G9+H9 -> 46093 | J9: =IFERROR(MAX(0,MIN(1,(TODAY()-G9)/(I9-G9))),"") -> 0 | K9: 0
A10: SHA | B10: Budget and BP | C10: Validate BP with Key Maaden Stakeholders | D10: Present the draft model and BP outputs to key Maaden stakeholders (technical and finance) for review. Incorporate feedback and resolve any open items. | E10: Hassen Moolla | F10: Not Started | G10: =I9 -> 46093 | H10: 3 | I10: =G10+H10 -> 46096 | J10: =IFERROR(MAX(0,MIN(1,(TODAY()-G10)/(I10-G10))),"") -> 0 | K10: 0
A11: SHA | B11: Budget and BP | C11: Package BP into Final Deliverable | D11: Define format/templates and develop final deliverables | E11: Hassen Moolla | F11: Not Started | G11: =I10 -> 46096 | H11: 7 | I11: =G11+H11 -> 46103 | J11: =IFERROR(MAX(0,MIN(1,(TODAY()-G11)/(I11-G11))),"") -> 0 | K11: 0
A12: SHA | B12: Budget and BP | C12: BP Final Deliverable validation | D12: Validate final deliverables | E12: Mohammed Al-Hamed | F12: Not Started | G12: =I11 -> 46103 | H12: 2 | I12: =G12+H12 -> 46105 | J12: =IFERROR(MAX(0,MIN(1,(TODAY()-G12)/(I12-G12))),"") -> 0 | K12: 0
A13: SHA | B13: Budget and BP | C13: Aramco Feedback on BP & Update | D13: Share the finalized BP with Aramco for review. Collect feedback, incorporate agreed changes, and lock the final version for approval | E13: Mohammed Al-Hamed | F13: Not Started | G13: =I12 -> 46105 | H13: 7 | I13: =G13+H13 -> 46112 | J13: =IFERROR(MAX(0,MIN(1,(TODAY()-G13)/(I13-G13))),"") -> 0 | K13: 0
B14: TSA | G14: =MIN(G15:G20) -> 46054 | H14: =I14-G14 -> 66 | I14: =MAX(I15:I20) -> 46120
A15: SHA | B15: TSA | C15: TSA Technical Services Catalogue | D15: Develop the catalogue of technical services to be provided by Maaden to the JV under the TSA, identify what services are to be provided by 3d parties | E15: Owen Hatton | F15: Completed | G15: 46054 | H15: 11 | I15: =G15+H15 -> 46065 | J15: =IFERROR(MAX(0,MIN(1,(TODAY()-G15)/(I15-G15))),"") -> 1 | K15: 1
A16: SHA | B16: TSA | C16: TSA Charge-out Rate Methodology | D16: Define the pricing methodology: establish the approach and basis for pricing each category of services (e.g., cost-plus, market benchmark, fixed fee) | E16: Hassen Moolla | F16: On-track | G16: =I15 -> 46065 | H16: 24 | I16: =G16+H16 -> 46089 | J16: =IFERROR(MAX(0,MIN(1,(TODAY()-G16)/(I16-G16))),"") -> 0.75 | K16: 1
A17: SHA | B17: TSA | C17: TSA Charge-out Rates Determination | D17: Apply the agreed pricing methodology to determine the applicable rates for each service in the catalogue | E17: Hassen Moolla | F17: Not Started | G17: =I16 -> 46089 | H17: 7 | I17: =G17+H17 -> 46096 | J17: =IFERROR(MAX(0,MIN(1,(TODAY()-G17)/(I17-G17))),"") -> 0 | K17: 0
A18: SHA | B18: TSA | C18: TSA Governance structure | D18: Define TSA governance structure and process: how TSA services are requested, approved, monitored, billed, paid, accounted (TSA management process) | E18: Muddassar | F18: Not Started | G18: 46085 | H18: 14 | I18: =G18+H18 -> 46099 | J18: =IFERROR(MAX(0,MIN(1,(TODAY()-G18)/(I18-G18))),"") -> 0 | K18: 0
A19: SHA | B19: TSA | C19: TSA Legal framework | D19: Finalize the TSA legal framework: draft and agree on the legal terms and conditions governing the provision of services, including scope, performance standards, liability, and termination provisions | E19: Aseel Alnafea | F19: Not Started | G19: =I18 -> 46099 | H19: 14 | I19: =G19+H19 -> 46113 | J19: =IFERROR(MAX(0,MIN(1,(TODAY()-G19)/(I19-G19))),"") -> 0 | K19: 0
A20: SHA | B20: TSA | C20: Aramco Feedback on TSA & Update | D20: Share the finalized TSA version with Aramco for review. Collect feedback, incorporate agreed changes, and lock the final version for approval. | E20: Muddassar Khan | F20: Not Started | G20: =I19 -> 46113 | H20: 7 | I20: =G20+H20 -> 46120 | J20: =IFERROR(MAX(0,MIN(1,(TODAY()-G20)/(I20-G20))),"") -> 0 | K20: 0
B21: GSA | G21: =MIN(G22:G27) -> 46054 | H21: =I21-G21 -> 66 | I21: =MAX(I22:I27) -> 46120
A22: SHA | B22: GSA | C22: GSA Catalogue of services | D22: Develop the catalogue of services to be provided by Maaden to the JV under the GSA | E22: Hassen Moolla | F22: On-track | G22: 46054 | H22: 35 | I22: =G22+H22 -> 46089 | J22: =IFERROR(MAX(0,MIN(1,(TODAY()-G22)/(I22-G22))),"") -> 0.82857143 | K22: 0.75
A23: SHA | B23: GSA | C23: GSA Charge-out Rate Methodology | D23: Define the pricing methodology: establish the approach and basis for pricing each category of services (e.g., cost-plus, market benchmark, fixed fee) | E23: Hassen Moolla | F23: On-track | G23: 46069 | H23: 24 | I23: =G23+H23 -> 46093 | J23: =IFERROR(MAX(0,MIN(1,(TODAY()-G23)/(I23-G23))),"") -> 0.58333333 | K23: 1
A24: SHA | B24: GSA | C24: GSA Charge-out Rates Determination | D24: Apply the agreed pricing methodology to determine the applicable rates for each service in the catalogue | E24: Hassen Moolla | F24: Not Started | G24: =I23 -> 46093 | H24: 7 | I24: =G24+H24 -> 46100 | J24: =IFERROR(MAX(0,MIN(1,(TODAY()-G24)/(I24-G24))),"") -> 0 | K24: 0
A25: SHA | B25: GSA | C25: GSA Governance structure | D25: Define GSA governance structure and process : how GSA services are requested, approved, monitored, billed, paid, accounted (GSA management process) | E25: Muddassar | F25: Not Started | G25: 46085 | H25: 14 | I25: =G25+H25 -> 46099 | J25: =IFERROR(MAX(0,MIN(1,(TODAY()-G25)/(I25-G25))),"") -> 0 | K25: 0
A26: SHA | B26: GSA | C26: GSA Legal framework | D26: Finalize the GSA legal framework: draft and agree on the legal terms and conditions governing the provision of services, including scope, performance standards, liability, and termination provisions | E26: Aseel Alnafea | F26: Not Started | G26: =I25 -> 46099 | H26: 14 | I26: =G26+H26 -> 46113 | J26: =IFERROR(MAX(0,MIN(1,(TODAY()-G26)/(I26-G26))),"") -> 0 | K26: 0
A27: SHA | B27: GSA | C27: Aramco Feedback on GSA & Update | D27: Share the finalized TSA version with Aramco for review. Collect feedback, incorporate agreed changes, and lock the final version for approval | E27: Muddassar Khan | F27: Not Started | G27: =I26 -> 46113 | H27: 7 | I27: =G27+H27 -> 46120 | J27: =IFERROR(MAX(0,MIN(1,(TODAY()-G27)/(I27-G27))),"") -> 0 | K27: 0
B28: DoA | G28: =MIN(G29:G31) -> 46068 | H28: =I28-G28 -> 37 | I28: =MAX(I29:I31) -> 46105
A29: SHA | B29: DoA | C29: Shareholders DoAs reference | D29: Obtain reference governance framework, obtain Maaden's existing Authority Matrix and Aramco's governance frameworks as benchmarks for the JV | E29: Mawiyah Alqaed | F29: On-track | G29: 46077 | H29: 9 | I29: =G29+H29 -> 46086 | J29: =IFERROR(MAX(0,MIN(1,(TODAY()-G29)/(I29-G29))),"") -> 0.66666667 | K29: 0.8
A30: SHA | B30: DoA | C30: Complete Design of DoA (Shedule 15) | D30: Design the multi-tiered financial approval matrix (incl governance and internal controls) : define approval tiers below Board thresholds across CAPEX, OPEX, contracts, procurement, HR, litigation, treasury, and asset management, aligned with SHA | E30: Omar Jabart | F30: On-track | G30: 46068 | H30: 30 | I30: =G30+H30 -> 46098 | J30: =IFERROR(MAX(0,MIN(1,(TODAY()-G30)/(I30-G30))),"") -> 0.5 | K30: 0.4
A31: SHA | B31: DoA | C31: Aramco Feedback on DoA & Update | D31: Share the finalized DoA version with Aramco for review. Collect feedback, incorporate agreed changes, and lock the final version for approval | E31: Muddassar/Mohammed | F31: Not Started | G31: =I30 -> 46098 | H31: 7 | I31: =G31+H31 -> 46105 | J31: =IFERROR(MAX(0,MIN(1,(TODAY()-G31)/(I31-G31))),"") -> 0 | K31: 0
B32: Secondment | G32: =MIN(G33:G36) -> 46054 | H32: =I32-G32 -> 62 | I32: =MAX(I33:I36) -> 46116
A33: SHA | B33: Secondment | C33: Secondment framework | D33: Develop secondment framework agreement (duration, cost basis, reporting lines, benefits) | E33: Rene Thumbran | F33: On-track | G33: 46054 | H33: 40 | I33: =G33+H33 -> 46094 | J33: =IFERROR(MAX(0,MIN(1,(TODAY()-G33)/(I33-G33))),"") -> 0.725 | K33: 0.6
A34: SHA | B34: Secondment | C34: Secondment Agreement Allocation Methodology | D34: Define cost allocation methodology and determine cost rates for secondees | E34: Rene Thumbran | F34: On-track | G34: 46055 | H34: 40 | I34: =G34+H34 -> 46095 | J34: =IFERROR(MAX(0,MIN(1,(TODAY()-G34)/(I34-G34))),"") -> 0.7 | K34: 0.6
A35: SHA | B35: Secondment | C35: JV Secondment Agreement draft | D35: Draft JV secondment agreement | E35: Aseel Alnafea | F35: Not Started | G35: =I34 -> 46095 | H35: 14 | I35: =G35+H35 -> 46109 | J35: =IFERROR(MAX(0,MIN(1,(TODAY()-G35)/(I35-G35))),"") -> 0 | K35: 0
A36: SHA | B36: Secondment | C36: Aramco Feedback on Secondment Agreement & Update | D36: Share the finalized Secondment Agreement with Aramco for review. Collect feedback, incorporate agreed changes, and lock the final version for approval | E36: Muddassar/Mohammed | F36: Not Started | G36: =I35 -> 46109 | H36: 7 | I36: =G36+H36 -> 46116 | J36: =IFERROR(MAX(0,MIN(1,(TODAY()-G36)/(I36-G36))),"") -> 0 | K36: 0
B37: SHA documentation | G37: =MIN(G38:G46) -> 46072 | H37: =I37-G37 -> 62 | I37: =MAX(I38:I46) -> 46134
A38: SHA | B38: SHA documentation | C38: SHA Sch.10 Guarantee for Permitted Transfers | D38: Agree Form of Guarantee for Permitted Transfers (Schedule 10) | E38: Muddassar Khan | F38: On-track | G38: 46072 | H38: 20 | I38: =G38+H38 -> 46092 | J38: =IFERROR(MAX(0,MIN(1,(TODAY()-G38)/(I38-G38))),"") -> 0.55 | K38: 0.25
A39: SHA | B39: SHA documentation | C39: SHA Sch.11 Form of the Agreement | D39: Finalize Form of Shareholder Services Agreement (Schedule 11) | E39: Muddassar Khan | F39: On-track | G39: 46072 | H39: 20 | I39: =G39+H39 -> 46092 | J39: =IFERROR(MAX(0,MIN(1,(TODAY()-G39)/(I39-G39))),"") -> 0.55 | K39: 0.25
A40: SHA | B40: SHA documentation | C40: SHA Sch.16 Economical assumptions | D40: Agree economic assumptions for technical studies (Schedule 16) - confirm applicability for Hard-Rock Exploration phase | E40: Muddassar Khan | F40: On-track | G40: 46072 | H40: 20 | I40: =G40+H40 -> 46092 | J40: =IFERROR(MAX(0,MIN(1,(TODAY()-G40)/(I40-G40))),"") -> 0.55 | K40: 0.25
A41: SHA | B41: SHA documentation | C41: SHA Sch.13 Competing business disclosure | D41: Complete existing competing businesses disclosure (Schedule 13) (action also required for aramco) | E41: Aseel Alnafea | F41: On-track | G41: 46077 | H41: 14 | I41: =G41+H41 -> 46091 | J41: =IFERROR(MAX(0,MIN(1,(TODAY()-G41)/(I41-G41))),"") -> 0.42857143 | K41: 0.25
...

Sheet Data Validation List
A1: Critical | B1: Status
A2: Yes | B2: Not Started
A3: No | B3: Delayed
B4: On-track
B5: Completed
