Workbook
Name POWER_USER_LINK_EDA81D4C_E424_4C6E_8A36_5F1A4994EB75: "Summary!R4C1:R17C2"

Sheet Cover
C7: Title | D7: Project Crystal - JV Day 1 Readiness Plan
C9: Description | D9: All actions required to achieve JV Day-1 operational readiness
C11: Date | D11: =TODAY() -> 46077

Sheet Summary
B2: REQUIREMENTS BY OWNER | C2: =SUM(C4:C29) -> 112 | D2: =SUM(D4:D29) -> 89 | E2: =SUM(E4:E29) -> 19 | F2: =SUM(F4:F29) -> 4 | G2: =SUM(G4:G29) -> 0 | I2: REQUIREMENTS BY WORKSTREAM | J2: =SUM(J4:J13) -> 116 | K2: =SUM(K4:K13) -> 93 | L2: =SUM(L4:L13) -> 19 | M2: =SUM(M4:M13) -> 4 | N2: =SUM(N4:N13) -> 0
B3: Owner | C3: Total | D3: Not started | E3: On-track | F3: Completed | G3: Delayed | I3: Workstream | J3: Total | K3: Not started | L3: On-track | M3: Completed | N3: Delayed
B4: Aseel Alnafea | C4: =SUM(D4:G4) -> 19 | D4: =(COUNTIFS('JV Readiness Plan'!$E:$E,$B4,'JV Readiness Plan'!$F:$F,D$3)) -> 19 | E4: =(COUNTIFS('JV Readiness Plan'!$E:$E,$B4,'JV Readiness Plan'!$F:$F,E$3)) -> 0 | F4: =(COUNTIFS('JV Readiness Plan'!$E:$E,$B4,'JV Readiness Plan'!$F:$F,F$3)) -> 0 | G4: =(COUNTIFS('JV Readiness Plan'!$E:$E,$B4,'JV Readiness Plan'!$F:$F,G$3)) -> 0 | I4: SHA | J4: =SUM(K4:N4) -> 46 | K4: =(COUNTIFS('JV Readiness Plan'!$A:$A,$I4,'JV Readiness Plan'!$F:$F,K$3)) -> 24 | L4: =(COUNTIFS('JV Readiness Plan'!$A:$A,$I4,'JV Readiness Plan'!$F:$F,L$3)) -> 18 | M4: =(COUNTIFS('JV Readiness Plan'!$A:$A,$I4,'JV Readiness Plan'!$F:$F,M$3)) -> 4 | N4: =(COUNTIFS('JV Readiness Plan'!$A:$A,$I4,'JV Readiness Plan'!$F:$F,N$3)) -> 0
B5: Muddassar | C5: =SUM(D5:G5) -> 14 | D5: =(COUNTIFS('JV Readiness Plan'!$E:$E,$B5,'JV Readiness Plan'!$F:$F,D$3)) -> 5 | E5: =(COUNTIFS('JV Readiness Plan'!$E:$E,$B5,'JV Readiness Plan'!$F:$F,E$3)) -> 7 | F5: =(COUNTIFS('JV Readiness Plan'!$E:$E,$B5,'JV Readiness Plan'!$F:$F,F$3)) -> 2 | G5: =(COUNTIFS('JV Readiness Plan'!$E:$E,$B5,'JV Readiness Plan'!$F:$F,G$3)) -> 0 | I5: Legal | J5: =SUM(K5:N5) -> 27 | K5: =(COUNTIFS('JV Readiness Plan'!$A:$A,$I5,'JV Readiness Plan'!$F:$F,K$3)) -> 27 | L5: =(COUNTIFS('JV Readiness Plan'!$A:$A,$I5,'JV Readiness Plan'!$F:$F,L$3)) -> 0 | M5: =(COUNTIFS('JV Readiness Plan'!$A:$A,$I5,'JV Readiness Plan'!$F:$F,M$3)) -> 0 | N5: =(COUNTIFS('JV Readiness Plan'!$A:$A,$I5,'JV Readiness Plan'!$F:$F,N$3)) -> 0
B6: Hassen Moolla | C6: =SUM(D6:G6) -> 13 | D6: =(COUNTIFS('JV Readiness Plan'!$E:$E,$B6,'JV Readiness Plan'!$F:$F,D$3)) -> 8 | E6: =(COUNTIFS('JV Readiness Plan'!$E:$E,$B6,'JV Readiness Plan'!$F:$F,E$3)) -> 4 | F6: =(COUNTIFS('JV Readiness Plan'!$E:$E,$B6,'JV Readiness Plan'!$F:$F,F$3)) -> 1 | G6: =(COUNTIFS('JV Readiness Plan'!$E:$E,$B6,'JV Readiness Plan'!$F:$F,G$3)) -> 0 | I6: Governance | J6: =SUM(K6:N6) -> 6 | K6: =(COUNTIFS('JV Readiness Plan'!$A:$A,$I6,'JV Readiness Plan'!$F:$F,K$3)) -> 6 | L6: =(COUNTIFS('JV Readiness Plan'!$A:$A,$I6,'JV Readiness Plan'!$F:$F,L$3)) -> 0 | M6: =(COUNTIFS('JV Readiness Plan'!$A:$A,$I6,'JV Readiness Plan'!$F:$F,M$3)) -> 0 | N6: =(COUNTIFS('JV Readiness Plan'!$A:$A,$I6,'JV Readiness Plan'!$F:$F,N$3)) -> 0
B7: Ramesh Murugesan | C7: =SUM(D7:G7) -> 10 | D7: =(COUNTIFS('JV Readiness Plan'!$E:$E,$B7,'JV Readiness Plan'!$F:$F,D$3)) -> 10 | E7: =(COUNTIFS('JV Readiness Plan'!$E:$E,$B7,'JV Readiness Plan'!$F:$F,E$3)) -> 0 | F7: =(COUNTIFS('JV Readiness Plan'!$E:$E,$B7,'JV Readiness Plan'!$F:$F,F$3)) -> 0 | G7: =(COUNTIFS('JV Readiness Plan'!$E:$E,$B7,'JV Readiness Plan'!$F:$F,G$3)) -> 0 | I7: Finance | J7: =SUM(K7:N7) -> 10 | K7: =(COUNTIFS('JV Readiness Plan'!$A:$A,$I7,'JV Readiness Plan'!$F:$F,K$3)) -> 10 | L7: =(COUNTIFS('JV Readiness Plan'!$A:$A,$I7,'JV Readiness Plan'!$F:$F,L$3)) -> 0 | M7: =(COUNTIFS('JV Readiness Plan'!$A:$A,$I7,'JV Readiness Plan'!$F:$F,M$3)) -> 0 | N7: =(COUNTIFS('JV Readiness Plan'!$A:$A,$I7,'JV Readiness Plan'!$F:$F,N$3)) -> 0
B8: Mawiyah Alqaed | C8: =SUM(D8:G8) -> 7 | D8: =(COUNTIFS('JV Readiness Plan'!$E:$E,$B8,'JV Readiness Plan'!$F:$F,D$3)) -> 6 | E8: =(COUNTIFS('JV Readiness Plan'!$E:$E,$B8,'JV Readiness Plan'!$F:$F,E$3)) -> 1 | F8: =(COUNTIFS('JV Readiness Plan'!$E:$E,$B8,'JV Readiness Plan'!$F:$F,F$3)) -> 0 | G8: =(COUNTIFS('JV Readiness Plan'!$E:$E,$B8,'JV Readiness Plan'!$F:$F,G$3)) -> 0 | I8: IT | J8: =SUM(K8:N8) -> 13 | K8: =(COUNTIFS('JV Readiness Plan'!$A:$A,$I8,'JV Readiness Plan'!$F:$F,K$3)) -> 12 | L8: =(COUNTIFS('JV Readiness Plan'!$A:$A,$I8,'JV Readiness Plan'!$F:$F,L$3)) -> 1 | M8: =(COUNTIFS('JV Readiness Plan'!$A:$A,$I8,'JV Readiness Plan'!$F:$F,M$3)) -> 0 | N8: =(COUNTIFS('JV Readiness Plan'!$A:$A,$I8,'JV Readiness Plan'!$F:$F,N$3)) -> 0
B9: Aseel Alnafea / Aramco Legal | C9: =SUM(D9:G9) -> 7 | D9: =(COUNTIFS('JV Readiness Plan'!$E:$E,$B9,'JV Readiness Plan'!$F:$F,D$3)) -> 7 | E9: =(COUNTIFS('JV Readiness Plan'!$E:$E,$B9,'JV Readiness Plan'!$F:$F,E$3)) -> 0 | F9: =(COUNTIFS('JV Readiness Plan'!$E:$E,$B9,'JV Readiness Plan'!$F:$F,F$3)) -> 0 | G9: =(COUNTIFS('JV Readiness Plan'!$E:$E,$B9,'JV Readiness Plan'!$F:$F,G$3)) -> 0 | I9: Procurement | J9: =SUM(K9:N9) -> 1 | K9: =(COUNTIFS('JV Readiness Plan'!$A:$A,$I9,'JV Readiness Plan'!$F:$F,K$3)) -> 1 | L9: =(COUNTIFS('JV Readiness Plan'!$A:$A,$I9,'JV Readiness Plan'!$F:$F,L$3)) -> 0 | M9: =(COUNTIFS('JV Readiness Plan'!$A:$A,$I9,'JV Readiness Plan'!$F:$F,M$3)) -> 0 | N9: =(COUNTIFS('JV Readiness Plan'!$A:$A,$I9,'JV Readiness Plan'!$F:$F,N$3)) -> 0
B10: Mohammed | C10: =SUM(D10:G10) -> 6 | D10: =(COUNTIFS('JV Readiness Plan'!$E:$E,$B10,'JV Readiness Plan'!$F:$F,D$3)) -> 4 | E10: =(COUNTIFS('JV Readiness Plan'!$E:$E,$B10,'JV Readiness Plan'!$F:$F,E$3)) -> 2 | F10: =(COUNTIFS('JV Readiness Plan'!$E:$E,$B10,'JV Readiness Plan'!$F:$F,F$3)) -> 0 | G10: =(COUNTIFS('JV Readiness Plan'!$E:$E,$B10,'JV Readiness Plan'!$F:$F,G$3)) -> 0 | I10: HR | J10: =SUM(K10:N10) -> 4 | K10: =(COUNTIFS('JV Readiness Plan'!$A:$A,$I10,'JV Readiness Plan'!$F:$F,K$3)) -> 4 | L10: =(COUNTIFS('JV Readiness Plan'!$A:$A,$I10,'JV Readiness Plan'!$F:$F,L$3)) -> 0 | M10: =(COUNTIFS('JV Readiness Plan'!$A:$A,$I10,'JV Readiness Plan'!$F:$F,M$3)) -> 0 | N10: =(COUNTIFS('JV Readiness Plan'!$A:$A,$I10,'JV Readiness Plan'!$F:$F,N$3)) -> 0
B11: Faraj Al Dossary | C11: =SUM(D11:G11) -> 6 | D11: =(COUNTIFS('JV Readiness Plan'!$E:$E,$B11,'JV Readiness Plan'!$F:$F,D$3)) -> 6 | E11: =(COUNTIFS('JV Readiness Plan'!$E:$E,$B11,'JV Readiness Plan'!$F:$F,E$3)) -> 0 | F11: =(COUNTIFS('JV Readiness Plan'!$E:$E,$B11,'JV Readiness Plan'!$F:$F,F$3)) -> 0 | G11: =(COUNTIFS('JV Readiness Plan'!$E:$E,$B11,'JV Readiness Plan'!$F:$F,G$3)) -> 0 | I11: HSSE | J11: =SUM(K11:N11) -> 5 | K11: =(COUNTIFS('JV Readiness Plan'!$A:$A,$I11,'JV Readiness Plan'!$F:$F,K$3)) -> 5 | L11: =(COUNTIFS('JV Readiness Plan'!$A:$A,$I11,'JV Readiness Plan'!$F:$F,L$3)) -> 0 | M11: =(COUNTIFS('JV Readiness Plan'!$A:$A,$I11,'JV Readiness Plan'!$F:$F,M$3)) -> 0 | N11: =(COUNTIFS('JV Readiness Plan'!$A:$A,$I11,'JV Readiness Plan'!$F:$F,N$3)) -> 0
B12: Rene Thumbran | C12: =SUM(D12:G12) -> 4 | D12: =(COUNTIFS('JV Readiness Plan'!$E:$E,$B12,'JV Readiness Plan'!$F:$F,D$3)) -> 2 | E12: =(COUNTIFS('JV Readiness Plan'!$E:$E,$B12,'JV Readiness Plan'!$F:$F,E$3)) -> 2 | F12: =(COUNTIFS('JV Readiness Plan'!$E:$E,$B12,'JV Readiness Plan'!$F:$F,F$3)) -> 0 | G12: =(COUNTIFS('JV Readiness Plan'!$E:$E,$B12,'JV Readiness Plan'!$F:$F,G$3)) -> 0 | I12: Comms | J12: =SUM(K12:N12) -> 3 | K12: =(COUNTIFS('JV Readiness Plan'!$A:$A,$I12,'JV Readiness Plan'!$F:$F,K$3)) -> 3 | L12: =(COUNTIFS('JV Readiness Plan'!$A:$A,$I12,'JV Readiness Plan'!$F:$F,L$3)) -> 0 | M12: =(COUNTIFS('JV Readiness Plan'!$A:$A,$I12,'JV Readiness Plan'!$F:$F,M$3)) -> 0 | N12: =(COUNTIFS('JV Readiness Plan'!$A:$A,$I12,'JV Readiness Plan'!$F:$F,N$3)) -> 0
B13: Muddassar / Mohammed | C13: =SUM(D13:G13) -> 3 | D13: =(COUNTIFS('JV Readiness Plan'!$E:$E,$B13,'JV Readiness Plan'!$F:$F,D$3)) -> 3 | E13: =(COUNTIFS('JV Readiness Plan'!$E:$E,$B13,'JV Readiness Plan'!$F:$F,E$3)) -> 0 | F13: =(COUNTIFS('JV Readiness Plan'!$E:$E,$B13,'JV Readiness Plan'!$F:$F,F$3)) -> 0 | G13: =(COUNTIFS('JV Readiness Plan'!$E:$E,$B13,'JV Readiness Plan'!$F:$F,G$3)) -> 0 | I13: Facilities | J13: =SUM(K13:N13) -> 1 | K13: =(COUNTIFS('JV Readiness Plan'!$A:$A,$I13,'JV Readiness Plan'!$F:$F,K$3)) -> 1 | L13: =(COUNTIFS('JV Readiness Plan'!$A:$A,$I13,'JV Readiness Plan'!$F:$F,L$3)) -> 0 | M13: =(COUNTIFS('JV Readiness Plan'!$A:$A,$I13,'JV Readiness Plan'!$F:$F,M$3)) -> 0 | N13: =(COUNTIFS('JV Readiness Plan'!$A:$A,$I13,'JV Readiness Plan'!$F:$F,N$3)) -> 0
B14: Susan Parker | C14: =SUM(D14:G14) -> 3 | D14: =(COUNTIFS('JV Readiness Plan'!$E:$E,$B14,'JV Readiness Plan'!$F:$F,D$3)) -> 3 | E14: =(COUNTIFS('JV Readiness Plan'!$E:$E,$B14,'JV Readiness Plan'!$F:$F,E$3)) -> 0 | F14: =(COUNTIFS('JV Readiness Plan'!$E:$E,$B14,'JV Readiness Plan'!$F:$F,F$3)) -> 0 | G14: =(COUNTIFS('JV Readiness Plan'!$E:$E,$B14,'JV Readiness Plan'!$F:$F,G$3)) -> 0
B15: Owen Hatton | C15: =SUM(D15:G15) -> 2 | D15: =(COUNTIFS('JV Readiness Plan'!$E:$E,$B15,'JV Readiness Plan'!$F:$F,D$3)) -> 0 | E15: =(COUNTIFS('JV Readiness Plan'!$E:$E,$B15,'JV Readiness Plan'!$F:$F,E$3)) -> 1 | F15: =(COUNTIFS('JV Readiness Plan'!$E:$E,$B15,'JV Readiness Plan'!$F:$F,F$3)) -> 1 | G15: =(COUNTIFS('JV Readiness Plan'!$E:$E,$B15,'JV Readiness Plan'!$F:$F,G$3)) -> 0
B16: Muddassar / Nuaim | C16: =SUM(D16:G16) -> 0 | D16: =(COUNTIFS('JV Readiness Plan'!$E:$E,$B16,'JV Readiness Plan'!$F:$F,D$3)) -> 0 | E16: =(COUNTIFS('JV Readiness Plan'!$E:$E,$B16,'JV Readiness Plan'!$F:$F,E$3)) -> 0 | F16: =(COUNTIFS('JV Readiness Plan'!$E:$E,$B16,'JV Readiness Plan'!$F:$F,F$3)) -> 0 | G16: =(COUNTIFS('JV Readiness Plan'!$E:$E,$B16,'JV Readiness Plan'!$F:$F,G$3)) -> 0
B17: Maaden and Aramco CEOs | C17: =SUM(D17:G17) -> 2 | D17: =(COUNTIFS('JV Readiness Plan'!$E:$E,$B17,'JV Readiness Plan'!$F:$F,D$3)) -> 2 | E17: =(COUNTIFS('JV Readiness Plan'!$E:$E,$B17,'JV Readiness Plan'!$F:$F,E$3)) -> 0 | F17: =(COUNTIFS('JV Readiness Plan'!$E:$E,$B17,'JV Readiness Plan'!$F:$F,F$3)) -> 0 | G17: =(COUNTIFS('JV Readiness Plan'!$E:$E,$B17,'JV Readiness Plan'!$F:$F,G$3)) -> 0
B18: Abdullah Alzamil | C18: =SUM(D18:G18) -> 2 | D18: =(COUNTIFS('JV Readiness Plan'!$E:$E,$B18,'JV Readiness Plan'!$F:$F,D$3)) -> 2 | E18: =(COUNTIFS('JV Readiness Plan'!$E:$E,$B18,'JV Readiness Plan'!$F:$F,E$3)) -> 0 | F18: =(COUNTIFS('JV Readiness Plan'!$E:$E,$B18,'JV Readiness Plan'!$F:$F,F$3)) -> 0 | G18: =(COUNTIFS('JV Readiness Plan'!$E:$E,$B18,'JV Readiness Plan'!$F:$F,G$3)) -> 0
B19: Hassen Moolla | C19: =SUM(D19:G19) -> 2 | D19: =(COUNTIFS('JV Readiness Plan'!$E:$E,$B19,'JV Readiness Plan'!$F:$F,D$3)) -> 2 | E19: =(COUNTIFS('JV Readiness Plan'!$E:$E,$B19,'JV Readiness Plan'!$F:$F,E$3)) -> 0 | F19: =(COUNTIFS('JV Readiness Plan'!$E:$E,$B19,'JV Readiness Plan'!$F:$F,F$3)) -> 0 | G19: =(COUNTIFS('JV Readiness Plan'!$E:$E,$B19,'JV Readiness Plan'!$F:$F,G$3)) -> 0
B20: Karim Mehboob | C20: =SUM(D20:G20) -> 2 | D20: =(COUNTIFS('JV Readiness Plan'!$E:$E,$B20,'JV Readiness Plan'!$F:$F,D$3)) -> 2 | E20: =(COUNTIFS('JV Readiness Plan'!$E:$E,$B20,'JV Readiness Plan'!$F:$F,E$3)) -> 0 | F20: =(COUNTIFS('JV Readiness Plan'!$E:$E,$B20,'JV Readiness Plan'!$F:$F,F$3)) -> 0 | G20: =(COUNTIFS('JV Readiness Plan'!$E:$E,$B20,'JV Readiness Plan'!$F:$F,G$3)) -> 0
B21: Marwan Sutan | C21: =SUM(D21:G21) -> 2 | D21: =(COUNTIFS('JV Readiness Plan'!$E:$E,$B21,'JV Readiness Plan'!$F:$F,D$3)) -> 2 | E21: =(COUNTIFS('JV Readiness Plan'!$E:$E,$B21,'JV Readiness Plan'!$F:$F,E$3)) -> 0 | F21: =(COUNTIFS('JV Readiness Plan'!$E:$E,$B21,'JV Readiness Plan'!$F:$F,F$3)) -> 0 | G21: =(COUNTIFS('JV Readiness Plan'!$E:$E,$B21,'JV Readiness Plan'!$F:$F,G$3)) -> 0
B22: Ramesh / Alex | C22: =SUM(D22:G22) -> 2 | D22: =(COUNTIFS('JV Readiness Plan'!$E:$E,$B22,'JV Readiness Plan'!$F:$F,D$3)) -> 1 | E22: =(COUNTIFS('JV Readiness Plan'!$E:$E,$B22,'JV Readiness Plan'!$F:$F,E$3)) -> 1 | F22: =(COUNTIFS('JV Readiness Plan'!$E:$E,$B22,'JV Readiness Plan'!$F:$F,F$3)) -> 0 | G22: =(COUNTIFS('JV Readiness Plan'!$E:$E,$B22,'JV Readiness Plan'!$F:$F,G$3)) -> 0
B23: Muddassar / Hassen | C23: =SUM(D23:G23) -> 1 | D23: =(COUNTIFS('JV Readiness Plan'!$E:$E,$B23,'JV Readiness Plan'!$F:$F,D$3)) -> 0 | E23: =(COUNTIFS('JV Readiness Plan'!$E:$E,$B23,'JV Readiness Plan'!$F:$F,E$3)) -> 1 | F23: =(COUNTIFS('JV Readiness Plan'!$E:$E,$B23,'JV Readiness Plan'!$F:$F,F$3)) -> 0 | G23: =(COUNTIFS('JV Readiness Plan'!$E:$E,$B23,'JV Readiness Plan'!$F:$F,G$3)) -> 0
B24: Aramco | C24: =SUM(D24:G24) -> 1 | D24: =(COUNTIFS('JV Readiness Plan'!$E:$E,$B24,'JV Readiness Plan'!$F:$F,D$3)) -> 1 | E24: =(COUNTIFS('JV Readiness Plan'!$E:$E,$B24,'JV Readiness Plan'!$F:$F,E$3)) -> 0 | F24: =(COUNTIFS('JV Readiness Plan'!$E:$E,$B24,'JV Readiness Plan'!$F:$F,F$3)) -> 0 | G24: =(COUNTIFS('JV Readiness Plan'!$E:$E,$B24,'JV Readiness Plan'!$F:$F,G$3)) -> 0
B25: Mawiyah Alqaed/Rene Thumbran? | C25: =SUM(D25:G25) -> 0 | D25: =(COUNTIFS('JV Readiness Plan'!$E:$E,$B25,'JV Readiness Plan'!$F:$F,D$3)) -> 0 | E25: =(COUNTIFS('JV Readiness Plan'!$E:$E,$B25,'JV Readiness Plan'!$F:$F,E$3)) -> 0 | F25: =(COUNTIFS('JV Readiness Plan'!$E:$E,$B25,'JV Readiness Plan'!$F:$F,F$3)) -> 0 | G25: =(COUNTIFS('JV Readiness Plan'!$E:$E,$B25,'JV Readiness Plan'!$F:$F,G$3)) -> 0
... B29: Raoof Madathil | C29: =SUM(D29:G29) -> 1 | D29: =(COUNTIFS('JV Readiness Plan'!$E:$E,$B29,'JV Readiness Plan'!$F:$F,D$3)) -> 1 | E29: =(COUNTIFS('JV Readiness Plan'!$E:$E,$B29,'JV Readiness Plan'!$F:$F,E$3)) -> 0 | F29: =(COUNTIFS('JV Readiness Plan'!$E:$E,$B29,'JV Readiness Plan'!$F:$F,F$3)) -> 0 | G29: =(COUNTIFS('JV Readiness Plan'!$E:$E,$B29,'JV Readiness Plan'!$F:$F,G$3)) -> 0

Sheet JV Readiness Plan
A1: PROJECT CRYSTAL - JV DAY-1 READINESS PLAN | H1: Day-1 target date | I1: =MAX(I4:I130) -> 46248
A3: Workstream | B3: Category | C3: Requirement | D3: Action | E3: Owner | F3: Status | G3: Start date | H3: Duration | I3: End date | J3: Target Completion (%) | K3: Notes
B4: Budget and Business Plan | G4: =MIN(G5:G13) -> 46054 | H4: =I4-G4 -> 51 | I4: =MAX(I5:I13) -> 46105
A5: SHA | B5: Budget and BP | C5: Align Roles, Responsibilities & Sources | D5: Clarify roles and responsibilities across Maaden finance and technical teams. Define who provides what, sources of information, and internal points of contact for each workstream. | E5: Hassen Moolla | F5: Completed | G5: 46054 | H5: 14 | I5: =G5+H5 -> 46068 | J5: =IFERROR(MAX(0,MIN(1,(TODAY()-G5)/(I5-G5))),"") -> 1
A6: SHA | B6: Budget and BP | C6: Identify Inputs & Assumptions | D6: Identify the full list of inputs and assumptions required to build the model. Define sources and providers for each item, and set deadlines for delivery. | E6: Hassen Moolla | F6: On-track | G6: =I5 -> 46068 | H6: 11 | I6: =G6+H6 -> 46079 | J6: =IFERROR(MAX(0,MIN(1,(TODAY()-G6)/(I6-G6))),"") -> 0.81818182
A7: SHA | B7: Budget and BP | C7: 5-Year Exploration Plan | D7: Develop 5-year Exploration Plan (2026-2030) | E7: Owen Hatton | F7: On-track | G7: =I5 -> 46068 | H7: 11 | I7: =G7+H7 -> 46079 | J7: =IFERROR(MAX(0,MIN(1,(TODAY()-G7)/(I7-G7))),"") -> 0.81818182
A8: SHA | B8: Budget and BP | C8: JV Day-1 Org Chart | D8: Finalize the Day-1 organization structure (confirm minimal technical staff requirements, including HSSE) | E8: Mohammed | F8: On-track | G8: 46071 | H8: 14 | I8: =G8+H8 -> 46085 | J8: =IFERROR(MAX(0,MIN(1,(TODAY()-G8)/(I8-G8))),"") -> 0.42857143
A9: SHA | B9: Budget and BP | C9: Build the Draft Model | D9: Construct the financial and operational model based on the defined inputs, assumptions, and agreed structure. Ensure formulas are robust and the model is auditable. | E9: Hassen Moolla | F9: Not Started | G9: =I7 -> 46079 | H9: 7 | I9: =G9+H9 -> 46086 | J9: =IFERROR(MAX(0,MIN(1,(TODAY()-G9)/(I9-G9))),"") -> 0
A10: SHA | B10: Budget and BP | C10: Validate with Key Maaden Stakeholders | D10: Present the draft model and BP outputs to key Maaden stakeholders (technical and finance) for review. Incorporate feedback and resolve any open items. | E10: Hassen Moolla | F10: Not Started | G10: =I9 -> 46086 | H10: 3 | I10: =G10+H10 -> 46089 | J10: =IFERROR(MAX(0,MIN(1,(TODAY()-G10)/(I10-G10))),"") -> 0
A11: SHA | B11: Budget and BP | C11: Package BP into Final Deliverable | D11: Define format/templates and develop final deliverables | E11: Hassen Moolla | F11: Not Started | G11: =I10 -> 46089 | H11: 7 | I11: =G11+H11 -> 46096 | J11: =IFERROR(MAX(0,MIN(1,(TODAY()-G11)/(I11-G11))),"") -> 0
A12: SHA | B12: Budget and BP | C12: BP Final Deliverable validation | D12: Validate final deliverables | E12: Mohammed | F12: Not Started | G12: =I11 -> 46096 | H12: 2 | I12: =G12+H12 -> 46098 | J12: =IFERROR(MAX(0,MIN(1,(TODAY()-G12)/(I12-G12))),"") -> 0
A13: SHA | B13: Budget and BP | C13: Obtain Feedback from Aramco & Update | D13: Share the finalized BP with Aramco for review. Collect feedback, incorporate agreed changes, and lock the final version for approval | E13: Mohammed | F13: Not Started | G13: =I12 -> 46098 | H13: 7 | I13: =G13+H13 -> 46105 | J13: =IFERROR(MAX(0,MIN(1,(TODAY()-G13)/(I13-G13))),"") -> 0
B14: TSA | G14: =MIN(G15:G20) -> 46054 | H14: =I14-G14 -> 63 | I14: =MAX(I15:I20) -> 46117
A15: SHA | B15: TSA | C15: Catalogue of technical services | D15: Develop the catalogue of technical services to be provided by Maaden to the JV under the TSA, identify what services are to be provided by 3d parties | E15: Owen Hatton | F15: Completed | G15: 46054 | H15: 11 | I15: =G15+H15 -> 46065 | J15: =IFERROR(MAX(0,MIN(1,(TODAY()-G15)/(I15-G15))),"") -> 1
A16: SHA | B16: TSA | C16: Charge-out rate | D16: Define the pricing methodology: establish the approach and basis for pricing each category of services (e.g., cost-plus, market benchmark, fixed fee) | E16: Hassen Moolla | F16: On-track | G16: =I15 -> 46065 | H16: 14 | I16: =G16+H16 -> 46079 | J16: =IFERROR(MAX(0,MIN(1,(TODAY()-G16)/(I16-G16))),"") -> 0.85714286
A17: SHA | B17: TSA | C17: Charge-out rate | D17: Apply the agreed pricing methodology to determine the applicable rates for each service in the catalogue | E17: Hassen Moolla | F17: Not Started | G17: =I16 -> 46079 | H17: 7 | I17: =G17+H17 -> 46086 | J17: =IFERROR(MAX(0,MIN(1,(TODAY()-G17)/(I17-G17))),"") -> 0
A18: SHA | B18: TSA | C18: Governance structure | D18: Define TSA governance structure and process: how TSA services are requested, approved, monitored, billed, paid, accounted (TSA management process) | E18: Muddassar / Nuaim / Aseel Alnafea | F18: Not Started | G18: 46082 | H18: 14 | I18: =G18+H18 -> 46096 | J18: =IFERROR(MAX(0,MIN(1,(TODAY()-G18)/(I18-G18))),"") -> 0 | K18: Waiting for Aramco's TSA - reference
A19: SHA | B19: TSA | C19: Legal framework | D19: Finalize the TSA legal framework: draft and agree on the legal terms and conditions governing the provision of services, including scope, performance standards, liability, and termination provisions | E19: Aseel Alnafea | F19: Not Started | G19: =I18 -> 46096 | H19: 14 | I19: =G19+H19 -> 46110 | J19: =IFERROR(MAX(0,MIN(1,(TODAY()-G19)/(I19-G19))),"") -> 0
A20: SHA | B20: TSA | C20: Obtain Feedback from Aramco & Update | D20: Share the finalized TSA version with Aramco for review. Collect feedback, incorporate agreed changes, and lock the final version for approval. | E20: Muddassar | F20: Not Started | G20: =I19 -> 46110 | H20: 7 | I20: =G20+H20 -> 46117 | J20: =IFERROR(MAX(0,MIN(1,(TODAY()-G20)/(I20-G20))),"") -> 0
B21: GSA | G21: =MIN(G22:G27) -> 46054 | H21: =I21-G21 -> 63 | I21: =MAX(I22:I27) -> 46117
A22: SHA | B22: GSA | C22: Catalogue of general services | D22: Develop the catalogue of services to be provided by Maaden to the JV under the GSA | E22: Hassen Moolla | F22: On-track | G22: 46054 | H22: 25 | I22: =G22+H22 -> 46079 | J22: =IFERROR(MAX(0,MIN(1,(TODAY()-G22)/(I22-G22))),"") -> 0.92
A23: SHA | B23: GSA | C23: Charge-out rate | D23: Define the pricing methodology: establish the approach and basis for pricing each category of services (e.g., cost-plus, market benchmark, fixed fee) | E23: Hassen Moolla | F23: On-track | G23: 46069 | H23: 10 | I23: =G23+H23 -> 46079 | J23: =IFERROR(MAX(0,MIN(1,(TODAY()-G23)/(I23-G23))),"") -> 0.8
A24: SHA | B24: GSA | C24: Charge-out rate | D24: Apply the agreed pricing methodology to determine the applicable rates for each service in the catalogue | E24: Hassen Moolla | F24: Not Started | G24: =I23 -> 46079 | H24: 7 | I24: =G24+H24 -> 46086 | J24: =IFERROR(MAX(0,MIN(1,(TODAY()-G24)/(I24-G24))),"") -> 0
A25: SHA | B25: GSA | C25: Governance structure | D25: Define GSA governance structure and process : how GSA services are requested, approved, monitored, billed, paid, accounted (GSA management process) | E25: Muddassar / Nuaim / Aseel Alnafea | F25: Not Started | G25: 46082 | H25: 14 | I25: =G25+H25 -> 46096 | J25: =IFERROR(MAX(0,MIN(1,(TODAY()-G25)/(I25-G25))),"") -> 0 | K25: Waiting for Aramco's TSA - reference
A26: SHA | B26: GSA | C26: Legal framework | D26: Finalize the GSA legal framework: draft and agree on the legal terms and conditions governing the provision of services, including scope, performance standards, liability, and termination provisions | E26: Aseel Alnafea | F26: Not Started | G26: =I25 -> 46096 | H26: 14 | I26: =G26+H26 -> 46110 | J26: =IFERROR(MAX(0,MIN(1,(TODAY()-G26)/(I26-G26))),"") -> 0
A27: SHA | B27: GSA | C27: Obtain Feedback from Aramco & Update | D27: Share the finalized TSA version with Aramco for review. Collect feedback, incorporate agreed changes, and lock the final version for approval | E27: Muddassar | F27: Not Started | G27: =I26 -> 46110 | H27: 7 | I27: =G27+H27 -> 46117 | J27: =IFERROR(MAX(0,MIN(1,(TODAY()-G27)/(I27-G27))),"") -> 0 | K27: STILL OPEN. Schedule 13 is completely empty. Each party needs to disclose their existing competing businesses. This is referenced in Clause 20.1(a)(i).STILL OPEN. Schedule 14 is completely empty. The funding notice templates need to be developed. Plus, the distinction between 'Form of Funding Notices' and 'Funding Request Notice template' is unclear in the SHA.
B28: DoA | G28: =MIN(G29:G31) -> 46068 | H28: =I28-G28 -> 37 | I28: =MAX(I29:I31) -> 46105
A29: SHA | B29: DoA | C29: Shareholders reference DoAs | D29: Obtain reference governance framework, obtain Maaden's existing Authority Matrix and Aramco's governance frameworks as benchmarks for the JV | E29: Mawiyah Alqaed | F29: Not Started | G29: 46077 | H29: 7 | I29: =G29+H29 -> 46084 | J29: =IFERROR(MAX(0,MIN(1,(TODAY()-G29)/(I29-G29))),"") -> 0
A30: SHA | B30: DoA | C30: Complete Design of DoA (Shedule 15) | D30: Design the multi-tiered financial approval matrix (incl governance and internal controls) : define approval tiers below Board thresholds across CAPEX, OPEX, contracts, procurement, HR, litigation, treasury, and asset management, aligned with SHA ceilings | E30: Mawiyah Alqaed | F30: On-track | G30: 46068 | H30: 30 | I30: =G30+H30 -> 46098 | J30: =IFERROR(MAX(0,MIN(1,(TODAY()-G30)/(I30-G30))),"") -> 0.3
A31: SHA | B31: DoA | C31: Obtain Feedback from Aramco & Update | D31: Share the finalized DoA version with Aramco for review. Collect feedback, incorporate agreed changes, and lock the final version for approval | E31: Muddassar / Mohammed | F31: Not Started | G31: =I30 -> 46098 | H31: 7 | I31: =G31+H31 -> 46105 | J31: =IFERROR(MAX(0,MIN(1,(TODAY()-G31)/(I31-G31))),"") -> 0
B32: Secondment | G32: =MIN(G33:G36) -> 46054 | H32: =I32-G32 -> 62 | I32: =MAX(I33:I36) -> 46116
A33: SHA | B33: Secondment | C33: Secondment framework | D33: Develop secondment framework agreement (duration, cost basis, reporting lines, benefits) | E33: Rene Thumbran | F33: On-track | G33: 46054 | H33: 40 | I33: =G33+H33 -> 46094 | J33: =IFERROR(MAX(0,MIN(1,(TODAY()-G33)/(I33-G33))),"") -> 0.575 | K33: Standard master framework
A34: SHA | B34: Secondment | C34: Allocation methodology | D34: Define cost allocation methodology and determine cost rates for secondees | E34: Rene Thumbran | F34: On-track | G34: 46055 | H34: 40 | I34: =G34+H34 -> 46095 | J34: =IFERROR(MAX(0,MIN(1,(TODAY()-G34)/(I34-G34))),"") -> 0.55
A35: SHA | B35: Secondment | C35: JV secondment agreement draft | D35: Draft JV secondment agreement | E35: Aseel Alnafea / Rene Thumbran | F35: Not Started | G35: =I34 -> 46095 | H35: 14 | I35: =G35+H35 -> 46109 | J35: =IFERROR(MAX(0,MIN(1,(TODAY()-G35)/(I35-G35))),"") -> 0
A36: SHA | B36: Secondment | C36: Obtain Feedback from Aramco & Update | D36: Share the finalized Secondment Agreement with Aramco for review. Collect feedback, incorporate agreed changes, and lock the final version for approval | E36: Muddassar / Mohammed | F36: Not Started | G36: =I35 -> 46109 | H36: 7 | I36: =G36+H36 -> 46116 | J36: =IFERROR(MAX(0,MIN(1,(TODAY()-G36)/(I36-G36))),"") -> 0
B37: SHA documentation | G37: =MIN(G38:G46) -> 46072 | H37: =I37-G37 -> 62 | I37: =MAX(I38:I46) -> 46134
A38: SHA | B38: SHA documentation | C38: Guarantee for Permitted Transfers | D38: Agree Form of Guarantee for Permitted Transfers (Schedule 10) | E38: Muddassar | F38: On-track | G38: 46072 | H38: 14 | I38: =G38+H38 -> 46086 | J38: =IFERROR(MAX(0,MIN(1,(TODAY()-G38)/(I38-G38))),"") -> 0.35714286 | K38: STILL OPEN. Schedule 10 is completely empty. Footnote 26 confirms this is still under discussion. Both parties need to agree on the form.
A39: SHA | B39: SHA documentation | C39: Finalization of the Agreement | D39: Finalize Form of Shareholder Services Agreement (Schedule 11) | E39: Muddassar | F39: On-track | G39: 46072 | H39: 14 | I39: =G39+H39 -> 46086 | J39: =IFERROR(MAX(0,MIN(1,(TODAY()-G39)/(I39-G39))),"") -> 0.35714286 | K39: STILL OPEN. Schedule 11 is entirely a placeholder. The substantive framework in Clause 21 exists, but the actual agreement form needs to be drafted. What exactly is this form? We understand GSA is a separament document, correct?
A40: SHA | B40: SHA documentation | C40: Economical assumptions | D40: Agree economic assumptions for technical studies (Schedule 16) - confirm applicability for Hard-Rock Exploration phase | E40: Muddassar | F40: On-track | G40: 46072 | H40: 14 | I40: =G40+H40 -> 46086 | J40: =IFERROR(MAX(0,MIN(1,(TODAY()-G40)/(I40-G40))),"") -> 0.35714286 | K40: CVA: do we really need this? This is only mentioned once on 15.12. Is this critical for SHA signing Mohammed: if needed, Muddassar to provide leveraging internal benchmarks (from other Maaden JVs?)
A41: SHA | B41: SHA documentation | C41: Competing business disclosure | D41: Complete existing competing businesses disclosure (Schedule 13) | E41: Aseel Alnafea / Aramco Legal | F41: Not Started | G41: 46077 | H41: 14 | I41: =G41+H41 -> 46091 | J41: =IFERROR(MAX(0,MIN(1,(TODAY()-G41)/(I41-G41))),"") -> 0 | K41: STILL OPEN. Schedule 13 is completely empty. Each party needs to disclose their existing competing businesses. This is referenced in Clause 20.1(a)(i).
...

Sheet Data Validation List
A1: Critical | B1: Status
A2: Yes | B2: Not Started
A3: No | B3: Delayed
B4: On-track
B5: Completed
